Workbook
Name date: #REF!
Name date: #REF!
Name date: #REF!
Name date: #REF!
Name date: #REF!
Name grad2: [1]เกณฑ์!$J$5:$N$9
Name grad3: [1]เกณฑ์!$J$12:$N$16
Name grade01: [1]เกณฑ์!$C$8:$G$16
Name group_sara: #REF!
Name group_sara: #REF!
Name group_sara: #REF!
Name group_sara: #REF!
Name group_sara: #REF!
Name kroo: #REF!
Name kroo: #REF!
Name kroo: #REF!
Name kroo: #REF!
Name kroo: #REF!
Name level_class: #REF!
Name level_class: #REF!
Name level_class: #REF!
Name level_class: #REF!
Name level_class: #REF!
Name level_ed: #REF!
Name level_ed: #REF!
Name level_ed: #REF!
Name level_ed: #REF!
Name level_ed: #REF!
Name list: #REF!
Name list: [2]Sheet1!$L$2:$L$13
Name month: #REF!
Name month: #REF!
Name month: #REF!
Name month: #REF!
Name month: #REF!
Name months: #REF!
Name months: #REF!
Name months: #REF!
Name months: #REF!
Name months: #REF!
Name posit: #REF!
Name posit: #REF!
Name posit: #REF!
Name posit: #REF!
Name posit: #REF!
Name scor1: #REF!
Name scor1: #REF!
Name scor1: #REF!
Name scor1: #REF!
Name scor1: #REF!
Name section: #REF!
Name section: #REF!
Name section: #REF!
Name section: #REF!
Name section: #REF!
Name time: #REF!
Name time: #REF!
Name time: #REF!
Name time: #REF!
Name time: #REF!

Sheet   ปก   
D6: แบบบันทึกผลการเรียนประจำรายวิชา ระดับประถมศึกษา
D7: โรงเรียน | F7: บ้านโพนแท่น | I7: อำเภอ | K7: เกษตรวิสัย | M7: จังหวัด | O7: ร้อยเอ็ด
K8: ปีการศึกษา | N8: 2568
C9: ชั้น ประถมศึกษาปีที่ 1 กลุ่มสาระการเรียนรู้ ภาษาต่างประเทศ
B10: รายวิชา ภาษาอังกฤษ | J10: รหัสวิชา | L10: อ 11101 | M10: เวลาเรียน | O10: 160 | P10: ชั่วโมง/ปีการศึกษา
D12: ครูผู้สอน
D13: ครูประจำชั้น | F13: นางสาวอำพร วรวงษ์, นางสาวปาณิสรา ญาติบำเรอ
C14: สรุปผลการประเมิน
C15: จำนวนนักเรียน | E15: ระดับผลการเรียน | M15: กิจกรรมพัฒนาผู้เรียน | P15: ผลการประเมิน
E16: 4 | F16: 3.5 | G16: 3 | H16: 2.5 | I16: 2 | J16: 1.5 | K16: 1 | L16: 0 | M16: ผ่าน | N16: ไม่ผ่าน | P16: ร | Q16: มส
C17: 13 | E17: =COUNTIF(คะแนน2!$U$5:$U$16, E16) -> 6 | F17: =COUNTIF(คะแนน2!$U$5:$U$16, F16) -> 2 | G17: =COUNTIF(คะแนน2!$U$5:$U$16, G16) -> 4 | H17: =COUNTIF(คะแนน2!$U$5:$U$16, H16) -> 0 | I17: =COUNTIF(คะแนน2!$U$5:$U$16, I16) -> 0 | J17: =COUNTIF(คะแนน2!$U$5:$U$16, J16) -> 0 | K17: =COUNTIF(คะแนน2!$U$5:$U$16, K16) -> 0 | L17: =COUNTIF(คะแนน2!$U$5:$U$16, L16) -> 0 | M17: 12 | N17: 0
C18: คิดเป็นร้อยละ | E18: =(E17*100)/$C$17 -> 46.153846 | F18: =(F17*100)/$C$17 -> 15.384615 | G18: =(G17*100)/$C$17 -> 30.769231 | H18: =(H17*100)/$C$17 -> 0 | I18: =(I17*100)/$C$17 -> 0 | J18: =(J17*100)/$C$17 -> 0 | K18: =(K17*100)/$C$17 -> 0 | L18: =(L17*100)/$C$17 -> 0 | M18: 100 | N18: 0
C20: ผลการประเมินคุณลักษณะอันพึงประสงค์ | L20: ผลการประเมินการอ่านคิดวิเคราะห์และเขียน
C21: 3 = ดีเยี่ยม | E21: 2 = ดี | G21: 1 = ผ่าน | I21: 0 = ไม่ผ่าน | L21: 3 = ดีเยี่ยม | N21: 2 = ดี | P21: 1 = ผ่าน | R21: 0 = ไม่ผ่าน
C22: =COUNTIF(คุณลักษณะ!$N$5:$N$16, "ดีเยี่ยม") -> 8 | E22: =COUNTIF(คุณลักษณะ!$N$5:$N$16, "ดี") -> 4 | G22: =COUNTIF(คุณลักษณะ!$N$5:$N$16, "ผ่าน") -> 0 | I22: =COUNTIF(คุณลักษณะ!$N$5:$N$16, "ไม่ผ่าน") -> 0 | K22: คน | L22: =COUNTIF(อ่านคิด!$O$5:$O$16, "ดีเยี่ยม") -> 8 | N22: =COUNTIF(อ่านคิด!$O$5:$O$16, "ดี") -> 4 | P22: =COUNTIF(อ่านคิด!$O$5:$O$16, "ผ่าน") -> 0 | R22: =COUNTIF(อ่านคิด!$O$5:$O$16, "ไม่ผ่าน") -> 0
C23: =(C22*100)/$C$17 -> 61.538462 | E23: =(E22*100)/$C$17 -> 30.769231 | G23: =(G22*100)/$C$17 -> 0 | I23: =(I22*100)/$C$17 -> 0 | K23: ร้อยละ | L23: =(L22*100)/$C$17 -> 61.538462 | N23: =(N22*100)/$C$17 -> 30.769231 | P23: =(P22*100)/$C$17 -> 0 | R23: =(R22*100)/$C$17 -> 0
C25: การอนุมัติผลการเรียน
E27: ลงชื่อ | F27: __________________________________ | L27: ครูผู้สอน
F28: (นางสาวอำพร วรวงษ์) | G28: (นายพิมล ตุ่นกระโทก)
E29: ลงชื่อ | F29: __________________________________ | L29: หัวหน้ากลุ่มสาระการเรียนรู้
F30: (นางอภิชญา ปะตาชาลี)
E31: ลงชื่อ | F31: __________________________________ | L31: หัวหน้างานวัดผลและประเมินผล
F32: (นางบัวลอย บัวไข)
C33: เรียนเสนอ เพื่อโปรดพิจารณา
E34: ลงชื่อ | F34: __________________________________ | L34: หัวหน้างานวิชาการ
F35: (นางดวงใจ วิจารย์)
C37: c | D37: อนุมัติ | F37: c | G37: ไม่อนุมัติ
I38: _________________________________
I39: (นางสาวพัทธ์ธีรา วารุรัง)
I40: ผู้อำนวยการโรงเรียนบ้านโพนแท่น
H41: วันที่ | I41: 31 | J41: เดือน | L41: มีนาคม พ.ศ. | N41: 2569

Sheet ข้อมูลเด็ก
C2: ข้อมูลนักเรียน
C3: เลขที่ | D3: เลขประจำตัว | E3: เลขประจำตัวประชาชน | F3: ชื่อ -สกุล | G3: วันเดือนปีเกิด | H3: หมายเหตุ
C6: 1 | D6: 1743 | E6: 1240600385503 | F6: เด็กชายปัณณวิชญ์ เปรียงพรม | G6: 16 ส.ค.61
C7: 2 | D7: 1744 | E7: 1459700117035 | F7: เด็กชายรัชชานนท์ เทียมกลาง | G7: 04 ก.ค.61
C8: 3 | D8: 1745 | E8: 1100401866090 | F8: เด็กชายรณกฤต สองเมือง | G8: 17 ธ.ค.61
C9: 4 | D9: 1746 | E9: 1459700121172 | F9: เด็กหญิงกรรณิการ์ คงสุดี | G9: 25 เม.ย.62
C10: 5 | D10: 1747 | E10: 1459700118244 | F10: เด็กหญิงชญานิศ พันธุเมฆ | G10: 19 ก.ย.61
C11: 6 | D11: 1748 | E11: 1459700119372 | F11: เด็กหญิงปนัดดา โพธิสุวรรณ | G11: 9 ธ.ค.61
C12: 7 | D12: 1749 | E12: 1749901694975 | F12: เด็กหญิงรุ่งนภา ผดุงภักดี | G12: 9 ก.ค.61
C13: 8 | D13: 1750 | E13: 1459901881999 | F13: เด็กหญิงพิมพิ์พิชชา มะลิมาตย์ | G13: 26 มี.ค.62
C14: 9 | D14: 1751 | E14: 1459700116861 | F14: เด็กหญิงพิมพ์รดา เม้าราษี | G14: 17 มิ.ย.61
C15: 10 | D15: 1752 | E15: 1459700117663 | F15: เด็กหญิงศศิวิมล ธนูทอง | G15: 17 ส.ค.61
C16: 11 | D16: 1753 | E16: 1459901857818 | F16: เด็กชายปัณณวิชญ์ พันธ์เดช | G16: 11ต.ค. 61
C17: 13 | D17: 1764 | E17: 1169200155082 | F17: เด็กหญิงสุชาดา ชมภูนาค | G17: 19 ต.ค. 60
C18: 12 | D18: 1764 | E18: 1459700118481 | F18: เด็กหญิงอริสา วรเลิศ | G18: 9 ต.ค. 61

Sheet วิธีทำ1
C2: การบันทึกเวลาเรียนและการบันทึกการประเมินผลการเรียนรู้
B3: การบันทึกเวลาเรียน
B4: 1. | C4: เลขประจำตัว ให้กรอกเลขประจำตัวจากน้อยไปหามาก และกรอกชื่อ – นามสกุล ให้ชัดเจน
B5: 2. | C5: เลขประจำตัวประชาชนให้กรอกตามข้อมูลที่ตรงกับสำเนาทะเบียนบ้าน
B6: 3. | C6: ส. 1- 40 คือ สัปดาห์ที่ 1-40 ในปีการศึกษา
B7: 4. | C7: วันที่ เดือน ปี ให้เขียนตัวย่อ ชั่วโมงเรียน สัปดาห์หนึ่งกำหนดไว้ 5 ช่อง คือ 5 วัน
B8: 5. | C8: การบันทึกเวลาเรียน ต้องบันทึกรายละเอียดดังนี้
C9: 5.1 | D9: จำนวนชั่วโมงที่.....ให้เขียน 1,2,3 ถ้าสอนหลายชั่วโมงวันเดียวกันหรือต่อเนื่องให้เขียน 1-2, 3-4
C10: 5.2 | D10: ผู้ที่มาเรียนให้ทำเครื่องหมาย "/"
C11: 5.2 | D11: ผู้ที่ไม่มาเรียนให้เขียน “ข” หรือ “ล”
C12: 5.4 | D12: ถ้านักเรียนลาพักการเรียนหรือลาออกระหว่างปี ให้ขีดเส้นตรงด้วยหมึกสีแดง ตั้งแต่วันพักการเรียนจนถึง
D13: วันสุดท้ายที่พักการเรียนหรือลาออก แล้วเขียนคำว่า “พักการเรียน” หรือ “ลาออก” ด้วยหมึกสีน้ำเงิน
C14: 5.5 | D14: รวมจำนวนชั่วโมงเรียนเมื่อสิ้นสุดภาคเรียน / สิ้นปีการศึกษา ให้รวมเวลาเรียนจริงลงในช่องรวมเวลาเรียน
D15: แล้วกรอกเวลาเรียนเต็มและเวลาเรียน 80 เปอร์เซ็นต์ของรายวิชานั้น ๆ ไว้ด้านบนและด้านล่างลงในช่อง
D16: นักเรียนที่มีเวลาเรียนไม่ถึง 80 เปอร์เซ็นต์ของรายวิชานั้นให้เขียนด้วยหมึกสีแดง
C17: 13
B18: บันทึกการประเมินผลการเรียนรู้
B19: 1. | C19: ให้เขียนตัวชี้วัดการเรียนรู้และคำอธิบายรายวิชาให้ละเอียด
B20: 2. | C20: เขียนอัตราส่วนของคะแนนระหว่างปีและปลายปี และกรอกรายละเอียดที่ส่วนบนกระดาษให้ละเอียด
B21: 3. | C21: การบันทึกผลการเรียนจะแยกออกเป็น ดังนี้
D22: 3.1. | E22: คะแนนผลการเรียนก่อนสอบวัดผลกลางปี
D23: 3.2. | E23: คะแนนผลการเรียนหลังสอบวัดผลกลางปี
D24: 3.3. | E24: คะแนนวัดผลกลางปี
D25: 3.4. | E25: คะแนนวัดผลปลายปี
B26: 4. | C26: ให้เขียนบันทึกคะแนนของแต่ละหน่วยการเรียนรู้ในช่องคะแนน เพื่อทราบผลการประเมินแต่ละครั้ง
C27: ก่อนสอบวัดผลกลางปี นำผลที่ได้กรอกในช่องรวมคะแนน
B28: 5. | C28: หลังสอบวัดผลกลางปี ให้เขียนบันทึกคะแนนของแต่ละหน่วยการเรียนรู้ในช่องคะแนนหลังสอบกลางปี
C29: เพื่อทราบผลการประเมินแต่ละครั้งก่อนสอบวัดผลปลายปี นำผลที่ได้กรอกในช่องรวมคะแนน
B30: 6. | C30: ให้เขียนบันทึกคะแนนสอบวัดผลกลางปีลงในช่องคะแนนกลางปี
B31: 7. | C31: รวมคะแนนก่อนกลางปีกับหลังกลางปี แล้วนำไปกรอกลงในช่องคะแนนรวมระหว่างเรียน
B32: 8. | C32: ให้เขียนบันทึกคะแนนสอบปลายปีลงช่องคะแนนปลายปี แล้วนำผลคะแนนรวมระหว่างเรียน
C33: กับคะแนนสอบปลายปีรวมกัน

Sheet วิธีทำ2
B2: 9. | C2: นำผลคะแนนที่ปรับแล้วไปเปรียบเทียบตามเกณฑ์ที่กำหนดดังนี้
E4: ระดับผลการเรียน | H4: ความหมาย | J4: เทียบกับระบบเปอร์เซ็นต์
E5: 4 | H5: ผลการเรียนดีเยี่ยม | J5: 80-100
E6: 3.5 | H6: ผลการเรียนดีมาก | J6: 75-79
E7: 3 | H7: ผลการเรียนดี | J7: 70-74
E8: 2.5 | H8: ผลการเรียนค่อนข้างดี | J8: 65-69
E9: 2 | H9: ผลการเรียนน่าพอใจ | J9: 60-64
E10: 1.5 | H10: ผลการเรียนพอใช้ | J10: 55-59
E11: 1 | H11: ผลการเรียนผ่านเกณฑ์ขั้นต่ำ | J11: 50-54
E12: 0 | H12: ผลการเรียนต่ำกว่าเกณฑ์ | J12: 0-49
B14: การประเมินคุณลักษณะอันพึงประสงค์
B15: 1. | C15: ผู้สอนมีหน้าที่ประเมินคุณลักษณะอันพึงประสงค์ ตามที่คณะกรรมการกำหนดคุณลักษณะ
C16: อันพึงประสงค์ของโรงเรียนที่กำหนดไว้
B17: 2. | C17: 13
B18: 3. | C18: การประเมินให้ประเมินเป็นรายภาคเรียนและตัดสินผลการเรียนรวมในชั้นสุดท้าย ของแต่ละช่วงชั้น
B19: 4. | C19: ความหมายของการประเมินคุณลักษณะอันพึงประสงค์
D20: 70 | E20: - | F20: 80 | G20: = | H20: ดีเยี่ยม
D21: 60 | E21: - | F21: 69 | G21: = | H21: ดี
D22: 50 | E22: - | F22: 59 | G22: = | H22: ผ่านเกณฑ์การประเมิน
B24: การประเมินการอ่าน คิดวิเคราะห์ และเขียน
B25: 1. | C25: ผู้สอนในสาระต่าง ๆ ควรจัดกิจกรรมที่ได้ฝึกและมีการประเมินความสามารถในการอ่าน คิดวิเคราะห์
C26: และเขียนสื่อความ อย่างเหมาะสมและมีคุณค่าตามศักยภาพแท้จริงของผู้เรียน
B27: 2. | C27: ผู้เรียนต้องผ่านการตรวจสอบหรือประเมินในการอ่าน คิดวิเคราะห์ และเขียนสื่อความได้คะแนน
C28: ไม่ต่ำกว่าร้อยละ 70
B29: 3. | C29: การประเมินให้ประเมินรายภาคเรียนและตัดสินผลการเรียนรวมในชั้นสุดท้าย ของแต่ละช่วงชั้น
B30: 4. | C30: ความหมายของการประเมินการอ่าน คิดวิเคราะห์ และเขียนสื่อความ
D31: 90 | E31: - | F31: 100 | G31: = | H31: ดีเยี่ยม
D32: 80 | E32: - | F32: 89 | G32: = | H32: ดี
D33: 70 | E33: - | F33: 79 | G33: = | H33: ผ่านเกณฑ์การประเมิน

Sheet เวลา1
B1: เลขที่ | C1: เลขประจำตัว | D1: เลขประจำตัว ประชาชน | E1: ชื่อ -สกุล | F1: สัปดาห์ | G1: 1 | J1: 2 | Q1: 3 | X1: 4
F2: เดือน | G2: พ.ค. | J2: พ.ค. | Q2: พ.ค. - มิ.ย. | X2: มิ.ย.
F3: วันที่ | G3: 16 | H3: 17 | I3: 18 | J3: 19 | K3: 20 | L3: 21 | M3: 22 | N3: 23 | O3: 24 | P3: 25 | Q3: 26 | R3: 27 | S3: 28 | T3: 29 | U3: 30 | V3: 31 | W3: 1 | X3: 2 | Y3: 3 | Z3: 4 | AA3: 5 | AB3: 6 | AC3: 7 | AD3: 8
F4: ชั่วโมงที่ | G4: ศ | H4: ส | I4: อา | J4: จ | K4: อ | L4: พ | M4: พฤ | N4: ศ | O4: ส | P4: อา | Q4: จ | R4: อ | S4: พ | T4: พฤ | U4: ศ | V4: ส | W4: อา | X4: จ | Y4: อ | Z4: พ | AA4: พฤ | AB4: ศ | AC4: ส | AD4: อา
B5: 1 | C5: 1743 | D5: =ข้อมูลเด็ก!E6 -> 1240600385503 | E5: =ข้อมูลเด็ก!F6 -> เด็กชายปัณณวิชญ์ เปรียงพรม | G5: / | J5: / | K5: / | L5: / | M5: / | N5: / | Q5: / | R5: / | S5: / | T5: / | U5: / | Z5: / | AA5: / | AB5: /
B6: 2 | C6: 1744 | D6: =ข้อมูลเด็ก!E7 -> 1459700117035 | E6: =ข้อมูลเด็ก!F7 -> เด็กชายรัชชานนท์ เทียมกลาง | G6: / | J6: / | K6: / | L6: / | M6: / | N6: / | Q6: / | R6: / | S6: / | T6: / | U6: / | Z6: / | AA6: / | AB6: /
B7: 3 | C7: 1745 | D7: =ข้อมูลเด็ก!E8 -> 1100401866090 | E7: =ข้อมูลเด็ก!F8 -> เด็กชายรณกฤต สองเมือง | G7: / | J7: / | K7: / | L7: / | M7: / | N7: / | Q7: / | R7: / | S7: / | T7: / | U7: / | Z7: / | AA7: / | AB7: /
B8: 4 | C8: 1746 | D8: =ข้อมูลเด็ก!E9 -> 1459700121172 | E8: =ข้อมูลเด็ก!F9 -> เด็กหญิงกรรณิการ์ คงสุดี | G8: / | J8: / | K8: / | L8: / | M8: / | N8: / | Q8: / | R8: / | S8: / | T8: / | U8: / | Z8: / | AA8: / | AB8: /
B9: 5 | C9: 1747 | D9: =ข้อมูลเด็ก!E10 -> 1459700118244 | E9: =ข้อมูลเด็ก!F10 -> เด็กหญิงชญานิศ พันธุเมฆ | G9: / | J9: / | K9: / | L9: / | M9: / | N9: / | Q9: / | R9: / | S9: / | T9: / | U9: / | Z9: / | AA9: / | AB9: /
B10: 6 | C10: 1748 | D10: =ข้อมูลเด็ก!E11 -> 1459700119372 | E10: =ข้อมูลเด็ก!F11 -> เด็กหญิงปนัดดา โพธิสุวรรณ | G10: / | J10: / | K10: / | L10: / | M10: / | N10: / | Q10: / | R10: / | S10: / | T10: / | U10: / | Z10: / | AA10: / | AB10: /
B11: 7 | C11: 1749 | D11: =ข้อมูลเด็ก!E12 -> 1749901694975 | E11: =ข้อมูลเด็ก!F12 -> เด็กหญิงรุ่งนภา ผดุงภักดี | G11: / | J11: / | K11: / | L11: / | M11: / | N11: / | Q11: / | R11: / | S11: / | T11: ล | U11: / | Z11: / | AA11: / | AB11: /
B12: 8 | C12: 1750 | D12: =ข้อมูลเด็ก!E13 -> 1459901881999 | E12: =ข้อมูลเด็ก!F13 -> เด็กหญิงพิมพิ์พิชชา มะลิมาตย์ | G12: / | J12: / | K12: / | L12: / | M12: / | N12: / | Q12: / | R12: / | S12: / | T12: / | U12: / | Z12: / | AA12: / | AB12: /
B13: 9 | C13: 1751 | D13: =ข้อมูลเด็ก!E14 -> 1459700116861 | E13: =ข้อมูลเด็ก!F14 -> เด็กหญิงพิมพ์รดา เม้าราษี | G13: / | J13: / | K13: / | L13: / | M13: / | N13: / | Q13: / | R13: / | S13: / | T13: / | U13: / | Z13: / | AA13: / | AB13: /
B14: 10 | C14: 1752 | D14: =ข้อมูลเด็ก!E15 -> 1459700117663 | E14: =ข้อมูลเด็ก!F15 -> เด็กหญิงศศิวิมล ธนูทอง | G14: / | J14: / | K14: / | L14: / | M14: / | N14: / | Q14: / | R14: / | S14: / | T14: / | U14: / | Z14: / | AA14: / | AB14: ข
B15: 11 | C15: 1753 | D15: =ข้อมูลเด็ก!E16 -> 1459901857818 | E15: =ข้อมูลเด็ก!F16 -> เด็กชายปัณณวิชญ์ พันธ์เดช | G15: / | J15: / | K15: / | L15: / | M15: / | N15: / | Q15: / | R15: / | S15: / | T15: / | U15: / | Z15: / | AA15: / | AB15: /
B16: 12 | C16: 1764 | D16: =ข้อมูลเด็ก!E17 -> 1169200155082 | E16: =ข้อมูลเด็ก!F17 -> เด็กหญิงสุชาดา ชมภูนาค | G16: / | J16: / | K16: / | L16: / | M16: / | N16: / | Q16: / | R16: / | S16: / | T16: / | U16: / | Z16: / | AA16: / | AB16: /
B17: 13 | C17: 1763 | D17: =ข้อมูลเด็ก!E18 -> 1459700118481 | E17: =ข้อมูลเด็ก!F18 -> เด็กหญิงอริสา วรเลิศ | G17: / | J17: / | K17: / | L17: / | M17: / | N17: / | Q17: / | R17: / | S17: / | T17: / | U17: / | Z17: / | AA17: / | AB17: /
D19: หมายเหตุ
D20: 2 มิถุนายน 2568 เป็นวันหยุดราชการพิเศษ
D21: 3 มิถุนายน 2568 หยุดชดเชยวันเฉลิมพระชนมพรรษาสมเด็จพระนางเจ้าฯ พระบรมราชินี

Sheet เวลา2
B1: สัปดาห์ | D1: 5 | J1: 6 | Q1: 7 | X1: 8 | AE1: 9 | AL1: 10 | AS1: 11
B2: เดือน | D2: มิ.ย. | J2: มิ.ย. | Q2: มิ.ย. | X2: มิ.ย. - ก.ค. | AE2: ก.ค. | AL2: ก.ค. | AS2: ก.ค.
B3: วันที่ | C3: 9 | D3: 10 | E3: 11 | F3: 12 | G3: 13 | H3: 14 | I3: 15 | J3: 16 | K3: 17 | L3: 18 | M3: 19 | N3: 20 | O3: 21 | P3: 22 | Q3: 23 | R3: 24 | S3: 25 | T3: 26 | U3: 27 | V3: 28 | W3: 29 | X3: 30 | Y3: 1 | Z3: 2 | AA3: 3 | AB3: 4 | AC3: 5 | AD3: 6 | AE3: 7 | AF3: 8 | AG3: 9 | AH3: 10 | AI3: 11 | AJ3: 12 | AK3: 13 | AL3: 14 | AM3: 15 | AN3: 16 | AO3: 17 | AP3: 18 | AQ3: 19 | AR3: 20 | AS3: 21 | AT3: 22 | AU3: 23 | AV3: 24 | AW3: 25 | AX3: 26 | AY3: 27
B4: ชั่วโมงที่ | C4: จ | D4: อ | E4: พ | F4: พฤ | G4: ศ | H4: ส | I4: อา | J4: จ | K4: อ | L4: พ | M4: พฤ | N4: ศ | O4: ส | P4: อา | Q4: จ | R4: อ | S4: พ | T4: พฤ | U4: ศ | V4: ส | W4: อา | X4: จ | Y4: อ | Z4: พ | AA4: พฤ | AB4: ศ | AC4: ส | AD4: อา | AE4: จ | AF4: อ | AG4: พ | AH4: พฤ | AI4: ศ | AJ4: ส | AK4: อา | AL4: จ | AM4: อ | AN4: พ | AO4: พฤ | AP4: ศ | AQ4: ส | AR4: อา | AS4: จ | AT4: อ | AU4: พ | AV4: พฤ | AW4: ศ | AX4: ส | AY4: อ
B5: 1 | C5: / | D5: / | E5: / | F5: / | G5: / | J5: / | K5: / | L5: / | M5: / | N5: / | Q5: / | R5: / | S5: / | T5: / | U5: / | X5: / | Y5: / | Z5: / | AA5: / | AB5: / | AE5: / | AF5: / | AG5: / | AL5: / | AM5: / | AN5: / | AO5: / | AP5: / | AS5: / | AT5: / | AU5: / | AV5: / | AW5: /
B6: 2 | C6: / | D6: / | E6: / | F6: / | G6: / | J6: / | K6: / | L6: / | M6: / | N6: / | Q6: / | R6: / | S6: / | T6: / | U6: / | X6: / | Y6: / | Z6: / | AA6: ข | AB6: / | AE6: / | AF6: / | AG6: / | AL6: / | AM6: / | AN6: / | AO6: / | AP6: / | AS6: / | AT6: / | AU6: / | AV6: / | AW6: /
B7: 3 | C7: / | D7: / | E7: / | F7: / | G7: / | J7: / | K7: / | L7: / | M7: / | N7: / | Q7: / | R7: / | S7: / | T7: / | U7: / | X7: / | Y7: / | Z7: / | AA7: / | AB7: / | AE7: / | AF7: / | AG7: / | AL7: / | AM7: / | AN7: ล | AO7: / | AP7: / | AS7: / | AT7: / | AU7: / | AV7: ข | AW7: /
B8: 4 | C8: / | D8: / | E8: / | F8: / | G8: ข | J8: / | K8: / | L8: / | M8: / | N8: / | Q8: / | R8: / | S8: / | T8: / | U8: / | X8: / | Y8: / | Z8: / | AA8: / | AB8: / | AE8: / | AF8: / | AG8: / | AL8: / | AM8: / | AN8: / | AO8: / | AP8: / | AS8: / | AT8: / | AU8: / | AV8: / | AW8: /
B9: 5 | C9: / | D9: / | E9: / | F9: / | G9: / | J9: / | K9: / | L9: / | M9: / | N9: / | Q9: / | R9: / | S9: / | T9: / | U9: / | X9: / | Y9: / | Z9: ล | AA9: / | AB9: / | AE9: / | AF9: / | AG9: / | AL9: / | AM9: / | AN9: ข | AO9: / | AP9: / | AS9: / | AT9: / | AU9: / | AV9: / | AW9: /
B10: 6 | C10: / | D10: / | E10: / | F10: / | G10: / | J10: / | K10: / | L10: / | M10: / | N10: / | Q10: / | R10: / | S10: / | T10: / | U10: / | X10: / | Y10: / | Z10: / | AA10: / | AB10: / | AE10: / | AF10: / | AG10: / | AL10: / | AM10: / | AN10: / | AO10: / | AP10: / | AS10: / | AT10: ล | AU10: / | AV10: / | AW10: /
B11: 7 | C11: / | D11: / | E11: / | F11: / | G11: / | J11: / | K11: / | L11: / | M11: / | N11: / | Q11: / | R11: ล | S11: / | T11: / | U11: / | X11: / | Y11: / | Z11: / | AA11: / | AB11: / | AE11: / | AF11: / | AG11: / | AL11: / | AM11: / | AN11: / | AO11: / | AP11: / | AS11: / | AT11: / | AU11: / | AV11: / | AW11: /
B12: 8 | C12: / | D12: / | E12: / | F12: / | G12: / | J12: / | K12: / | L12: / | M12: / | N12: / | Q12: / | R12: / | S12: / | T12: / | U12: / | X12: / | Y12: / | Z12: / | AA12: / | AB12: / | AE12: / | AF12: / | AG12: / | AL12: / | AM12: / | AN12: / | AO12: / | AP12: / | AS12: / | AT12: / | AU12: / | AV12: / | AW12: /
B13: 9 | C13: / | D13: / | E13: / | F13: / | G13: / | J13: / | K13: / | L13: / | M13: / | N13: / | Q13: / | R13: / | S13: / | T13: / | U13: / | X13: / | Y13: / | Z13: / | AA13: / | AB13: / | AE13: / | AF13: / | AG13: / | AL13: / | AM13: / | AN13: / | AO13: / | AP13: / | AS13: / | AT13: / | AU13: / | AV13: / | AW13: /
B14: 10 | C14: / | D14: / | E14: / | F14: / | G14: / | J14: / | K14: / | L14: / | M14: / | N14: / | Q14: / | R14: / | S14: / | T14: / | U14: / | X14: / | Y14: / | Z14: / | AA14: / | AB14: / | AE14: / | AF14: / | AG14: / | AL14: / | AM14: / | AN14: / | AO14: / | AP14: / | AS14: ล | AT14: / | AU14: / | AV14: / | AW14: /
B15: 11 | C15: / | D15: / | E15: / | F15: / | G15: / | J15: / | K15: / | L15: / | M15: / | N15: / | Q15: / | R15: / | S15: / | T15: / | U15: / | X15: / | Y15: / | Z15: ข | AA15: / | AB15: / | AE15: / | AF15: / | AG15: / | AL15: / | AM15: / | AN15: ล | AO15: / | AP15: / | AS15: / | AT15: / | AU15: / | AV15: / | AW15: /
B16: 12 | C16: / | D16: / | E16: / | F16: / | G16: / | J16: / | K16: / | L16: / | M16: / | N16: / | Q16: / | R16: / | S16: / | T16: / | U16: / | X16: / | Y16: / | Z16: / | AA16: / | AB16: / | AE16: / | AF16: / | AG16: / | AL16: / | AM16: / | AN16: / | AO16: / | AP16: / | AS16: / | AT16: / | AU16: / | AV16: / | AW16: /
B17: 13 | C17: / | D17: / | E17: / | F17: / | G17: / | J17: / | K17: / | L17: / | M17: / | N17: / | Q17: / | R17: / | S17: / | T17: / | U17: / | X17: / | Y17: / | Z17: / | AA17: / | AB17: / | AE17: / | AF17: / | AG17: / | AL17: / | AM17: / | AN17: / | AO17: / | AP17: / | AS17: / | AT17: / | AU17: / | AV17: / | AW17: /
C18: 13
E19: หมายเหตุ
E20: 10 กรกฎาคม 2568 หยุดวันอาสาฬหบูชา
E21: 11 กรกฎาคม 2568 หยุดวันเข้าพรรษา

Sheet เวลา3
B1: สัปดาห์ | C1: 12 | J1: 13 | Q1: 14 | X1: 15 | AE1: 16 | AL1: 17 | AS1: 18
B2: เดือน | C2: ก.ค. -ส.ค. | J2: ส.ค. | Q2: ส.ค. | X2: ส.ค. | AE2: ส.ค. | AL2: ก.ย. | AS2: ก.ย.
B3: วันที่ | C3: 28 | D3: 29 | E3: 30 | F3: 31 | G3: 1 | H3: 2 | I3: 3 | J3: 4 | K3: 5 | L3: 6 | M3: 7 | N3: 8 | O3: 9 | P3: 10 | Q3: 11 | R3: 12 | S3: 13 | T3: 14 | U3: 15 | V3: 16 | W3: 17 | X3: 18 | Y3: 19 | Z3: 20 | AA3: 21 | AB3: 22 | AC3: 23 | AD3: 24 | AE3: 25 | AF3: 26 | AG3: 27 | AH3: 28 | AI3: 29 | AJ3: 30 | AK3: 31 | AL3: 1 | AM3: 2 | AN3: 3 | AO3: 4 | AP3: 5 | AQ3: 6 | AR3: 7 | AS3: 8 | AT3: 9 | AU3: 10 | AV3: 11 | AW3: 12 | AX3: 13 | AY3: 14
B4: ชั่วโมงที่ | C4: จ | D4: อ | E4: พ | F4: พฤ | G4: ศ | H4: ส | I4: อา | J4: จ | K4: อ | L4: พ | M4: พฤ | N4: ศ | O4: ส | P4: อา | Q4: จ | R4: อ | S4: พ | T4: พฤ | U4: ศ | V4: ส | W4: อา | X4: จ | Y4: อ | Z4: พ | AA4: พฤ | AB4: ศ | AC4: ส | AD4: อา | AE4: จ | AF4: อ | AG4: พ | AH4: พฤ | AI4: ศ | AJ4: ส | AK4: อา | AL4: จ | AM4: อ | AN4: พ | AO4: พฤ | AP4: ศ | AQ4: ส | AR4: อา | AS4: จ | AT4: อ | AU4: พ | AV4: พฤ | AW4: ศ | AX4: ส | AY4: อ
B5: 1 | D5: / | E5: / | F5: / | G5: / | J5: / | K5: / | L5: / | M5: / | N5: / | Q5: / | S5: / | T5: / | U5: / | X5: / | Y5: / | Z5: ข | AA5: / | AB5: / | AE5: / | AF5: / | AG5: / | AH5: / | AI5: / | AL5: / | AM5: / | AN5: / | AO5: / | AP5: / | AS5: / | AT5: / | AU5: / | AV5: / | AW5: /
B6: 2 | D6: / | E6: / | F6: / | G6: / | J6: / | K6: / | L6: / | M6: / | N6: / | Q6: / | S6: / | T6: / | U6: / | X6: / | Y6: / | Z6: / | AA6: / | AB6: / | AE6: / | AF6: / | AG6: / | AH6: / | AI6: / | AL6: / | AM6: / | AN6: / | AO6: / | AP6: / | AS6: / | AT6: / | AU6: / | AV6: / | AW6: /
B7: 3 | D7: / | E7: / | F7: / | G7: / | J7: / | K7: / | L7: / | M7: / | N7: / | Q7: / | S7: / | T7: / | U7: / | X7: / | Y7: / | Z7: / | AA7: / | AB7: / | AE7: / | AF7: / | AG7: / | AH7: / | AI7: / | AL7: / | AM7: / | AN7: / | AO7: / | AP7: / | AS7: / | AT7: / | AU7: / | AV7: / | AW7: /
B8: 4 | D8: / | E8: / | F8: / | G8: / | J8: / | K8: / | L8: / | M8: / | N8: / | Q8: / | S8: / | T8: / | U8: / | X8: / | Y8: / | Z8: / | AA8: / | AB8: / | AE8: / | AF8: / | AG8: / | AH8: / | AI8: / | AL8: / | AM8: / | AN8: / | AO8: / | AP8: / | AS8: / | AT8: / | AU8: ข | AV8: / | AW8: /
B9: 5 | D9: / | E9: / | F9: ล | G9: / | J9: / | K9: / | L9: / | M9: / | N9: / | Q9: / | S9: / | T9: / | U9: / | X9: / | Y9: / | Z9: / | AA9: / | AB9: / | AE9: / | AF9: / | AG9: / | AH9: / | AI9: / | AL9: / | AM9: / | AN9: / | AO9: / | AP9: / | AS9: / | AT9: / | AU9: / | AV9: / | AW9: /
B10: 6 | D10: / | E10: / | F10: / | G10: / | J10: / | K10: / | L10: / | M10: / | N10: / | Q10: / | S10: / | T10: / | U10: / | X10: / | Y10: / | Z10: / | AA10: / | AB10: / | AE10: / | AF10: / | AG10: / | AH10: / | AI10: / | AL10: / | AM10: / | AN10: / | AO10: / | AP10: / | AS10: / | AT10: / | AU10: / | AV10: / | AW10: /
B11: 7 | D11: / | E11: / | F11: / | G11: / | J11: / | K11: / | L11: / | M11: / | N11: / | Q11: / | S11: / | T11: ข | U11: / | X11: / | Y11: / | Z11: / | AA11: / | AB11: / | AE11: / | AF11: / | AG11: / | AH11: / | AI11: / | AL11: / | AM11: / | AN11: / | AO11: / | AP11: / | AS11: / | AT11: / | AU11: / | AV11: / | AW11: /
B12: 8 | D12: / | E12: / | F12: / | G12: / | J12: / | K12: / | L12: / | M12: / | N12: / | Q12: / | S12: / | T12: / | U12: / | X12: / | Y12: / | Z12: / | AA12: / | AB12: / | AE12: / | AF12: / | AG12: / | AH12: / | AI12: / | AL12: / | AM12: / | AN12: / | AO12: / | AP12: / | AS12: / | AT12: / | AU12: / | AV12: / | AW12: /
B13: 9 | D13: / | E13: / | F13: / | G13: / | J13: / | K13: / | L13: / | M13: / | N13: / | Q13: / | S13: / | T13: / | U13: / | X13: / | Y13: / | Z13: / | AA13: / | AB13: / | AE13: / | AF13: / | AG13: / | AH13: / | AI13: / | AL13: / | AM13: / | AN13: / | AO13: ข | AP13: / | AS13: / | AT13: / | AU13: / | AV13: / | AW13: /
B14: 10 | D14: / | E14: / | F14: / | G14: / | J14: / | K14: / | L14: / | M14: / | N14: / | Q14: / | S14: / | T14: / | U14: / | X14: / | Y14: / | Z14: / | AA14: / | AB14: / | AE14: / | AF14: / | AG14: / | AH14: / | AI14: / | AL14: / | AM14: / | AN14: / | AO14: / | AP14: / | AS14: / | AT14: / | AU14: / | AV14: / | AW14: /
B15: 11 | D15: / | E15: / | F15: / | G15: / | J15: / | K15: / | L15: / | M15: / | N15: / | Q15: / | S15: / | T15: / | U15: / | X15: / | Y15: / | Z15: / | AA15: / | AB15: / | AE15: / | AF15: / | AG15: / | AH15: / | AI15: / | AL15: / | AM15: / | AN15: / | AO15: / | AP15: / | AS15: / | AT15: / | AU15: / | AV15: / | AW15: /
B16: 12 | D16: / | E16: / | F16: / | G16: / | J16: / | K16: / | L16: / | M16: / | N16: / | Q16: / | S16: / | T16: / | U16: / | X16: ข | Y16: / | Z16: / | AA16: / | AB16: / | AE16: / | AF16: / | AG16: / | AH16: / | AI16: / | AL16: / | AM16: / | AN16: / | AO16: / | AP16: / | AS16: / | AT16: / | AU16: / | AV16: / | AW16: /
B17: 13 | D17: / | E17: / | F17: / | G17: / | J17: / | K17: / | L17: / | M17: / | N17: / | Q17: / | S17: / | T17: / | U17: / | X17: / | Y17: / | Z17: / | AA17: / | AB17: / | AE17: / | AF17: / | AG17: / | AH17: / | AI17: / | AL17: / | AM17: / | AN17: / | AO17: / | AP17: / | AS17: / | AT17: / | AU17: / | AV17: / | AW17: /
C18: 13
C19: หมายเหตุ
C20: 28 กรกฎาคม 2568 หยุดวันเฉลิมพระชนพรรษาพระบาทสมเด็จพระเจ้าอยู่หัว (รัชกาลที่ 10)
C21: 12 สิงหาคม 2567 หยุดวันเฉลิมพระพรรษาสมเด็จพระนางเจ้าสิริกิติ์

Sheet เวลา 4
B1: สัปดาห์ | C1: 19 | J1: 20 | Q1: 21 | X1: 22 | AB1: 23 | AG1: 24 | AN1: 25
B2: เดือน | C2: ก.ย. | J2: ก.ย. | Q2: ก.ย - ต.ค | X2: ต.ค. | AB2: พ.ย. | AG2: พ.ย. | AN2: พ.ย.
B3: วันที่ | C3: 15 | D3: 16 | E3: 17 | F3: 18 | G3: 19 | H3: 20 | I3: 21 | J3: 22 | K3: 23 | L3: 24 | M3: 25 | N3: 26 | O3: 27 | P3: 28 | Q3: 29 | R3: 30 | S3: 1 | T3: 2 | U3: 3 | V3: 4 | W3: 5 | X3: 6 | Y3: 7 | Z3: 8 | AA3: 9 | AB3: 1 | AC3: 2 | AD3: 3 | AE3: 4 | AF3: 5 | AG3: 6 | AH3: 7 | AI3: 8 | AJ3: 9 | AK3: 10 | AL3: 11 | AM3: 12 | AN3: 13 | AO3: 14 | AP3: 15 | AQ3: 16 | AR3: 17
B4: ชั่วโมงที่ | C4: จ | D4: อ | E4: พ | F4: พฤ | G4: ศ | H4: ส | I4: อา | J4: จ | K4: อ | L4: พ | M4: พฤ | N4: ศ | O4: ส | P4: อา | Q4: จ | R4: อ | S4: พ | T4: พฤ | U4: ศ | V4: ส | W4: อา | X4: จ | Y4: อ | Z4: พ | AA4: พฤ | AB4: ส | AC4: อา | AD4: จ | AE4: อ | AF4: พ | AG4: พฤ | AH4: ศ | AI4: ส | AJ4: อ | AK4: จ | AL4: อ | AM4: พ | AN4: พฤ | AO4: ศ | AP4: ส | AQ4: อา | AR4: จ
B5: 1 | C5: / | D5: / | E5: / | F5: / | G5: / | J5: / | K5: / | L5: / | M5: / | N5: / | Q5: / | R5: / | S5: / | T5: / | U5: / | X5: / | Y5: / | Z5: / | AA5: / | AD5: / | AE5: / | AF5: / | AG5: / | AH5: / | AK5: / | AL5: / | AM5: / | AN5: / | AO5: / | AR5: /
B6: 2 | C6: / | D6: / | E6: / | F6: / | G6: / | J6: / | K6: / | L6: / | M6: / | N6: / | Q6: / | R6: / | S6: / | T6: / | U6: / | X6: / | Y6: / | Z6: ข | AA6: / | AD6: / | AE6: / | AF6: / | AG6: / | AH6: / | AK6: / | AL6: / | AM6: / | AN6: / | AO6: / | AR6: /
B7: 3 | C7: / | D7: / | E7: / | F7: / | G7: / | J7: / | K7: / | L7: / | M7: / | N7: / | Q7: / | R7: / | S7: / | T7: / | U7: / | X7: / | Y7: / | Z7: / | AA7: / | AD7: / | AE7: / | AF7: / | AG7: / | AH7: / | AK7: / | AL7: / | AM7: / | AN7: / | AO7: ข | AR7: /
B8: 4 | C8: / | D8: / | E8: / | F8: / | G8: / | J8: / | K8: / | L8: / | M8: / | N8: / | Q8: / | R8: / | S8: / | T8: / | U8: / | X8: / | Y8: / | Z8: / | AA8: / | AD8: / | AE8: / | AF8: / | AG8: / | AH8: / | AK8: / | AL8: / | AM8: / | AN8: / | AO8: / | AR8: /
B9: 5 | C9: / | D9: / | E9: / | F9: / | G9: / | J9: / | K9: / | L9: / | M9: / | N9: / | Q9: / | R9: / | S9: / | T9: / | U9: / | X9: / | Y9: / | Z9: ข | AA9: / | AD9: / | AE9: / | AF9: / | AG9: / | AH9: / | AK9: / | AL9: / | AM9: / | AN9: / | AO9: / | AR9: /
B10: 6 | C10: / | D10: / | E10: / | F10: / | G10: / | J10: / | K10: / | L10: / | M10: / | N10: / | Q10: / | R10: / | S10: / | T10: / | U10: / | X10: / | Y10: / | Z10: / | AA10: / | AD10: / | AE10: / | AF10: / | AG10: / | AH10: / | AK10: / | AL10: / | AM10: ล | AN10: / | AO10: / | AR10: /
B11: 7 | C11: / | D11: / | E11: / | F11: / | G11: / | J11: / | K11: / | L11: / | M11: / | N11: / | Q11: / | R11: / | S11: / | T11: / | U11: / | X11: / | Y11: / | Z11: / | AA11: / | AD11: / | AE11: / | AF11: / | AG11: / | AH11: / | AK11: / | AL11: / | AM11: / | AN11: / | AO11: / | AR11: /
B12: 8 | C12: / | D12: / | E12: / | F12: / | G12: / | J12: / | K12: / | L12: / | M12: / | N12: / | Q12: / | R12: / | S12: / | T12: / | U12: / | X12: / | Y12: / | Z12: / | AA12: / | AD12: / | AE12: / | AF12: / | AG12: / | AH12: / | AK12: / | AL12: / | AM12: / | AN12: / | AO12: / | AR12: /
B13: 9 | C13: / | D13: / | E13: / | F13: ล | G13: / | J13: / | K13: / | L13: / | M13: / | N13: / | Q13: / | R13: / | S13: / | T13: / | U13: / | X13: / | Y13: / | Z13: / | AA13: / | AD13: / | AE13: / | AF13: / | AG13: / | AH13: / | AK13: / | AL13: / | AM13: / | AN13: / | AO13: / | AR13: /
B14: 10 | C14: / | D14: / | E14: / | F14: / | G14: / | J14: / | K14: / | L14: / | M14: / | N14: / | Q14: / | R14: / | S14: / | T14: / | U14: / | X14: / | Y14: / | Z14: / | AA14: / | AD14: / | AE14: / | AF14: / | AG14: / | AH14: / | AK14: / | AL14: / | AM14: / | AN14: / | AO14: / | AR14: /
B15: 11 | C15: / | D15: / | E15: / | F15: / | G15: / | J15: / | K15: / | L15: / | M15: / | N15: / | Q15: / | R15: / | S15: / | T15: / | U15: / | X15: / | Y15: / | Z15: / | AA15: / | AD15: / | AE15: ข | AF15: / | AG15: / | AH15: / | AK15: / | AL15: / | AM15: / | AN15: / | AO15: / | AR15: /
B16: 12 | C16: / | D16: / | E16: / | F16: / | G16: / | J16: / | K16: ล | L16: / | M16: / | N16: / | Q16: / | R16: / | S16: / | T16: / | U16: / | X16: / | Y16: / | Z16: / | AA16: / | AD16: / | AE16: / | AF16: / | AG16: / | AH16: / | AK16: / | AL16: / | AM16: / | AN16: / | AO16: / | AR16: /
B17: 13 | C17: / | D17: / | E17: / | F17: / | G17: / | J17: / | K17: / | L17: / | M17: / | N17: / | Q17: / | R17: / | S17: / | T17: / | U17: / | X17: / | Y17: / | Z17: / | AA17: / | AD17: / | AE17: / | AF17: / | AG17: / | AH17: / | AK17: / | AL17: / | AM17: / | AN17: / | AO17: / | AR17: /
C18: 13
F19: หมายเหตุ
F20: 11 - 31 ตุลาคม 2568 ปิดภาคเรียนที่ 1 ปีการศึกษา 2568

Sheet เวลา 5
B1: สัปดาห์ | C1: 26 | I1: 27 | P1: 28 | W1: 29 | AD1: 30 | AK1: 31 | AR1: 32
B2: เดือน | C2: พ.ย. | I2: พ.ย. | P2: ธ.ค. | W2: ธ.ค. | AD2: ธ.ค. | AK2: ธ.ค. | AR2: ธ.ค. - ม.ค.
B3: วันที่ | C3: 18 | D3: 19 | E3: 20 | F3: 21 | G3: 22 | H3: 23 | I3: 24 | J3: 25 | K3: 26 | L3: 27 | M3: 28 | N3: 29 | O3: 30 | P3: 1 | Q3: 2 | R3: 3 | S3: 4 | T3: 5 | U3: 6 | V3: 7 | W3: 8 | X3: 9 | Y3: 10 | Z3: 11 | AA3: 12 | AB3: 13 | AC3: 14 | AD3: 15 | AE3: 16 | AF3: 17 | AG3: 18 | AH3: 19 | AI3: 20 | AJ3: 21 | AK3: 22 | AL3: 23 | AM3: 24 | AN3: 25 | AO3: 26 | AP3: 27 | AQ3: 28 | AR3: 29 | AS3: 30 | AT3: 31 | AU3: 1 | AV3: 2 | AW3: 3 | AX3: 4
B4: ชั่วโมงที่ | C4: อ | D4: พ | E4: พฤ | F4: ศ | G4: ส | H4: อา | I4: จ | J4: อ | K4: พ | L4: พฤ | M4: ศ | N4: ส | O4: อา | P4: จ | Q4: อ | R4: พ | S4: พฤ | T4: ศ | U4: ส | V4: อา | W4: จ | X4: อ | Y4: พ | Z4: พฤ | AA4: ศ | AB4: ส | AC4: อา | AD4: จ | AE4: อ | AF4: พ | AG4: พฤ | AH4: ศ | AI4: ส | AJ4: อา | AK4: จ | AL4: อ | AM4: พ | AN4: พฤ | AO4: ศ | AP4: ส | AQ4: อา | AR4: จ | AS4: อ | AT4: พ | AU4: พฤ | AV4: ศ | AW4: ส | AX4: อา
B5: 1 | C5: / | D5: / | E5: / | F5: / | I5: / | J5: / | K5: / | L5: / | M5: / | P5: / | Q5: / | R5: / | S5: / | W5: / | X5: / | Z5: / | AA5: / | AD5: / | AE5: / | AF5: / | AG5: / | AH5: / | AK5: / | AL5: / | AM5: / | AN5: / | AO5: / | AR5: / | AS5: / | AV5: /
B6: 2 | C6: / | D6: / | E6: / | F6: / | I6: / | J6: / | K6: / | L6: / | M6: / | P6: / | Q6: / | R6: / | S6: / | W6: / | X6: / | Z6: / | AA6: / | AD6: / | AE6: / | AF6: / | AG6: / | AH6: / | AK6: / | AL6: / | AM6: / | AN6: / | AO6: / | AR6: / | AS6: / | AV6: /
B7: 3 | C7: / | D7: / | E7: / | F7: / | I7: / | J7: / | K7: / | L7: / | M7: / | P7: / | Q7: / | R7: / | S7: / | W7: / | X7: / | Z7: / | AA7: / | AD7: / | AE7: / | AF7: / | AG7: / | AH7: / | AK7: / | AL7: / | AM7: / | AN7: / | AO7: / | AR7: / | AS7: / | AV7: /
B8: 4 | C8: / | D8: / | E8: / | F8: / | I8: / | J8: / | K8: / | L8: / | M8: / | P8: / | Q8: / | R8: / | S8: / | W8: / | X8: / | Z8: / | AA8: / | AD8: / | AE8: / | AF8: / | AG8: / | AH8: / | AK8: / | AL8: / | AM8: / | AN8: / | AO8: / | AR8: / | AS8: / | AV8: /
B9: 5 | C9: / | D9: / | E9: / | F9: / | I9: / | J9: / | K9: / | L9: / | M9: / | P9: / | Q9: / | R9: / | S9: / | W9: / | X9: / | Z9: / | AA9: / | AD9: / | AE9: / | AF9: / | AG9: / | AH9: / | AK9: / | AL9: / | AM9: / | AN9: / | AO9: / | AR9: / | AS9: ล | AV9: /
B10: 6 | C10: / | D10: / | E10: / | F10: / | I10: / | J10: ข | K10: / | L10: / | M10: / | P10: / | Q10: / | R10: / | S10: / | W10: / | X10: / | Z10: / | AA10: / | AD10: / | AE10: / | AF10: / | AG10: / | AH10: / | AK10: / | AL10: / | AM10: / | AN10: / | AO10: / | AR10: / | AS10: / | AV10: /
B11: 7 | C11: / | D11: / | E11: / | F11: / | I11: / | J11: / | K11: / | L11: / | M11: / | P11: / | Q11: / | R11: / | S11: / | W11: / | X11: / | Z11: / | AA11: / | AD11: / | AE11: / | AF11: / | AG11: / | AH11: / | AK11: / | AL11: / | AM11: / | AN11: / | AO11: / | AR11: / | AS11: / | AV11: /
B12: 8 | C12: / | D12: / | E12: / | F12: / | I12: / | J12: / | K12: / | L12: / | M12: / | P12: / | Q12: / | R12: / | S12: / | W12: / | X12: / | Z12: / | AA12: / | AD12: / | AE12: / | AF12: / | AG12: / | AH12: / | AK12: / | AL12: / | AM12: / | AN12: / | AO12: / | AR12: / | AS12: / | AV12: /
B13: 9 | C13: / | D13: / | E13: / | F13: / | I13: / | J13: / | K13: / | L13: / | M13: / | P13: / | Q13: / | R13: / | S13: / | W13: / | X13: / | Z13: / | AA13: / | AD13: / | AE13: / | AF13: / | AG13: / | AH13: / | AK13: / | AL13: / | AM13: / | AN13: ล | AO13: / | AR13: / | AS13: / | AV13: /
B14: 10 | C14: / | D14: / | E14: / | F14: / | I14: / | J14: / | K14: / | L14: / | M14: / | P14: / | Q14: / | R14: / | S14: / | W14: / | X14: / | Z14: / | AA14: / | AD14: / | AE14: / | AF14: / | AG14: / | AH14: / | AK14: / | AL14: / | AM14: / | AN14: / | AO14: / | AR14: / | AS14: / | AV14: /
B15: 11 | C15: / | D15: / | E15: / | F15: / | I15: / | J15: / | K15: / | L15: ข | M15: / | P15: / | Q15: / | R15: / | S15: / | W15: / | X15: / | Z15: / | AA15: / | AD15: / | AE15: / | AF15: / | AG15: / | AH15: / | AK15: / | AL15: / | AM15: / | AN15: / | AO15: / | AR15: / | AS15: / | AV15: /
B16: 12 | C16: / | D16: / | E16: / | F16: / | I16: / | J16: / | K16: / | L16: / | M16: / | P16: / | Q16: / | R16: / | S16: / | W16: / | X16: / | Z16: / | AA16: / | AD16: / | AE16: / | AF16: / | AG16: / | AH16: / | AK16: / | AL16: / | AM16: / | AN16: / | AO16: / | AR16: / | AS16: / | AV16: /
B17: 13 | C17: / | D17: / | E17: / | F17: / | I17: / | J17: / | K17: / | L17: / | M17: / | P17: / | Q17: / | R17: / | S17: / | W17: / | X17: / | Z17: / | AA17: / | AD17: / | AE17: / | AF17: / | AG17: / | AH17: / | AK17: / | AL17: / | AM17: / | AN17: / | AO17: / | AR17: / | AS17: / | AV17: /
C18: 13
L19: หมายเหตุ
D21: วันที่ 5 หยุดวันพ่อแห่งชาติ รัชกาลที่ 9
F22: วันที่ 10 หยุดวันรัฐธรรมนูญ
F23: วันที่ 31 หยุดวันสิ้นปี
F24: 1มกราคม 2567 วันขึ้นปีใหม่

Sheet เวลา 6
B1: สัปดาห์ | C1: 33 | I1: 34 | P1: 35 | W1: 36 | AD1: 37 | AK1: 38 | AR1: 39
B2: เดือน | C2: ม.ค. | I2: ม.ค. | P2: ม.ค. | W2: ม.ค. | AD2: ก.พ. | AK2: ก.พ. | AR2: ก.พ.
B3: วันที่ | C3: 5 | D3: 6 | E3: 7 | F3: 8 | G3: 9 | H3: 10 | I3: 11 | J3: 12 | K3: 13 | L3: 14 | M3: 15 | N3: 16 | O3: 17 | P3: 18 | Q3: 19 | R3: 20 | S3: 21 | T3: 22 | U3: 23 | V3: 24 | W3: 25 | X3: 26 | Y3: 27 | Z3: 28 | AA3: 29 | AB3: 30 | AC3: 31 | AD3: 1 | AE3: 2 | AF3: 3 | AG3: 4 | AH3: 5 | AI3: 6 | AJ3: 7 | AK3: 8 | AL3: 9 | AM3: 10 | AN3: 11 | AO3: 12 | AP3: 13 | AQ3: 14 | AR3: 15 | AS3: 16 | AT3: 17 | AU3: 18 | AV3: 19 | AW3: 20 | AX3: 21
B4: ชั่วโมงที่ | C4: จ | D4: อ | E4: พ | F4: พฤ | G4: ศ | H4: ส | I4: อา | J4: จ | K4: อ | L4: พ | M4: พฤ | N4: ศ | O4: ส | P4: อา | Q4: จ | R4: อ | S4: พ | T4: พฤ | U4: ศ | V4: ส | W4: อา | X4: จ | Y4: อ | Z4: พ | AA4: พฤ | AB4: ศ | AC4: ส | AD4: อา | AE4: จ | AF4: อ | AG4: พ | AH4: พฤ | AI4: ศ | AJ4: ส | AK4: อา | AL4: จ | AM4: อ | AN4: พ | AO4: พฤ | AP4: ศ | AQ4: ส | AR4: อา | AS4: จ | AT4: อ | AU4: พ | AV4: พฤ | AW4: ศ | AX4: ล
B5: 1 | C5: / | D5: / | E5: / | F5: / | G5: / | J5: / | K5: / | L5: / | M5: / | N5: / | Q5: ข | R5: / | S5: / | T5: / | U5: / | X5: / | Y5: / | Z5: / | AA5: / | AB5: / | AE5: / | AF5: / | AG5: / | AH5: / | AI5: / | AL5: / | AM5: / | AN5: / | AO5: / | AP5: / | AS5: / | AT5: / | AU5: / | AV5: / | AW5: /
B6: 2 | C6: / | D6: / | E6: / | F6: / | G6: / | J6: / | K6: / | L6: / | M6: / | N6: / | Q6: / | R6: / | S6: / | T6: / | U6: / | X6: / | Y6: / | Z6: / | AA6: / | AB6: / | AE6: / | AF6: / | AG6: / | AH6: / | AI6: / | AL6: / | AM6: / | AN6: / | AO6: / | AP6: / | AS6: / | AT6: / | AU6: / | AV6: / | AW6: /
B7: 3 | C7: / | D7: / | E7: / | F7: / | G7: / | J7: / | K7: / | L7: / | M7: / | N7: / | Q7: / | R7: / | S7: / | T7: / | U7: / | X7: / | Y7: / | Z7: / | AA7: / | AB7: / | AE7: / | AF7: / | AG7: / | AH7: / | AI7: / | AL7: / | AM7: / | AN7: / | AO7: / | AP7: / | AS7: / | AT7: / | AU7: ข | AV7: / | AW7: /
B8: 4 | C8: / | D8: / | E8: / | F8: / | G8: / | J8: / | K8: / | L8: / | M8: / | N8: / | Q8: / | R8: / | S8: / | T8: / | U8: / | X8: / | Y8: / | Z8: ข | AA8: / | AB8: / | AE8: / | AF8: / | AG8: / | AH8: / | AI8: / | AL8: / | AM8: / | AN8: / | AO8: / | AP8: / | AS8: / | AT8: / | AU8: / | AV8: / | AW8: /
B9: 5 | C9: / | D9: / | E9: / | F9: / | G9: / | J9: / | K9: / | L9: / | M9: / | N9: / | Q9: / | R9: / | S9: / | T9: / | U9: / | X9: / | Y9: / | Z9: / | AA9: / | AB9: / | AE9: / | AF9: / | AG9: / | AH9: / | AI9: / | AL9: / | AM9: / | AN9: / | AO9: / | AP9: / | AS9: / | AT9: / | AU9: / | AV9: / | AW9: /
B10: 6 | C10: / | D10: / | E10: / | F10: / | G10: / | J10: / | K10: / | L10: / | M10: / | N10: / | Q10: / | R10: / | S10: / | T10: / | U10: / | X10: / | Y10: / | Z10: / | AA10: / | AB10: / | AE10: / | AF10: / | AG10: / | AH10: / | AI10: / | AL10: / | AM10: / | AN10: / | AO10: / | AP10: / | AS10: / | AT10: / | AU10: / | AV10: / | AW10: /
B11: 7 | C11: ล | D11: / | E11: / | F11: / | G11: / | J11: / | K11: / | L11: / | M11: / | N11: / | Q11: / | R11: / | S11: / | T11: / | U11: / | X11: / | Y11: / | Z11: / | AA11: / | AB11: / | AE11: / | AF11: / | AG11: / | AH11: / | AI11: / | AL11: / | AM11: / | AN11: / | AO11: / | AP11: / | AS11: / | AT11: / | AU11: / | AV11: / | AW11: /
B12: 8 | C12: / | D12: / | E12: / | F12: / | G12: / | J12: / | K12: / | L12: / | M12: / | N12: / | Q12: / | R12: / | S12: / | T12: / | U12: / | X12: / | Y12: / | Z12: / | AA12: / | AB12: / | AE12: / | AF12: / | AG12: / | AH12: / | AI12: / | AL12: / | AM12: / | AN12: / | AO12: / | AP12: / | AS12: / | AT12: / | AU12: / | AV12: / | AW12: /
B13: 9 | C13: / | D13: / | E13: / | F13: / | G13: / | J13: / | K13: / | L13: / | M13: / | N13: / | Q13: / | R13: / | S13: / | T13: / | U13: / | X13: / | Y13: / | Z13: / | AA13: / | AB13: / | AE13: / | AF13: / | AG13: / | AH13: / | AI13: / | AL13: / | AM13: / | AN13: / | AO13: / | AP13: / | AS13: / | AT13: / | AU13: / | AV13: / | AW13: /
B14: 10 | C14: / | D14: / | E14: / | F14: / | G14: / | J14: / | K14: / | L14: / | M14: / | N14: / | Q14: / | R14: / | S14: / | T14: / | U14: / | X14: / | Y14: / | Z14: / | AA14: / | AB14: / | AE14: / | AF14: / | AG14: / | AH14: / | AI14: / | AL14: / | AM14: / | AN14: / | AO14: / | AP14: / | AS14: / | AT14: / | AU14: / | AV14: / | AW14: /
B15: 11 | C15: / | D15: / | E15: / | F15: / | G15: / | J15: / | K15: / | L15: / | M15: / | N15: / | Q15: / | R15: / | S15: / | T15: / | U15: / | X15: / | Y15: / | Z15: / | AA15: / | AB15: / | AE15: / | AF15: / | AG15: / | AH15: / | AI15: / | AL15: / | AM15: / | AN15: / | AO15: / | AP15: / | AS15: / | AT15: / | AU15: / | AV15: / | AW15: /
B16: 12 | C16: / | D16: / | E16: / | F16: / | G16: / | J16: / | K16: / | L16: / | M16: / | N16: / | Q16: / | R16: / | S16: / | T16: / | U16: / | X16: / | Y16: / | Z16: / | AA16: / | AB16: / | AE16: / | AF16: / | AG16: / | AH16: / | AI16: / | AL16: / | AM16: / | AN16: / | AO16: / | AP16: / | AS16: / | AT16: / | AU16: / | AV16: / | AW16: /
B17: 13 | C17: / | D17: / | E17: / | F17: / | G17: / | J17: / | K17: / | L17: / | M17: / | N17: / | Q17: / | R17: / | S17: / | T17: / | U17: / | X17: / | Y17: / | Z17: / | AA17: / | AB17: / | AE17: / | AF17: / | AG17: / | AH17: / | AI17: / | AL17: / | AM17: / | AN17: / | AO17: / | AP17: / | AS17: / | AT17: / | AU17: / | AV17: / | AW17: /
C18: 13
D19: หมายเหตุ
D20: 16 มกราคม 2568 วันครู
D21: 12 กุมภาพันธ์ 2568 วันมาฆบูชา

Sheet เวลา 7
B1: สัปดาห์ | C1: 40 | AK1: รวมเวลาเรียน
B2: เดือน | C2: ก.พ. | J2: มี.ค. | Q2: มี.ค. | X2: มี.ค. | AE2: มี.ค. | AK2: รวมลา | AL2: รวมขาด | AM2: รวมมา | AN2: ร้อยละ
B3: วันที่ | C3: 22 | D3: 23 | E3: 24 | F3: 25 | G3: 26 | H3: 27 | I3: 28 | J3: 1 | K3: 2 | L3: 3 | M3: 4 | N3: 5 | O3: 6 | P3: 7 | Q3: 8 | R3: 9 | S3: 10 | T3: 11 | U3: 12 | V3: 13 | W3: 14 | X3: 15 | Y3: 16 | Z3: 17 | AA3: 18 | AB3: 19 | AC3: 20 | AD3: 21 | AE3: 22 | AF3: 23 | AG3: 24 | AH3: 25 | AI3: 26 | AJ3: 27
B4: ชั่วโมงที่ | C4: อา | D4: จ | E4: อ | F4: พ | G4: พฤ | H4: ศ | I4: ส | J4: อา | K4: จ | L4: อ | M4: พ | N4: พฤ | O4: ศ | P4: ส | Q4: อา | R4: จ | S4: อ | T4: พ | U4: พฤ | V4: ศ | W4: ส | X4: อา | Y4: จ | Z4: อ | AA4: พ | AB4: พฤ | AC4: ศ | AD4: ส | AE4: อา | AF4: จ | AG4: อ | AH4: พ | AI4: พฤ | AJ4: ศ
B5: 1 | D5: / | E5: / | F5: / | G5: / | H5: / | K5: / | L5: / | M5: / | N5: / | O5: / | R5: / | S5: / | T5: / | U5: / | V5: / | Y5: / | Z5: / | AA5: / | AB5: / | AC5: / | AF5: / | AG5: / | AH5: / | AI5: / | AJ5: / | AK5: {=_xlfn.LET(_xlpm.TotalCount, COUNTIF(D5:AJ5, "ล") + COUNTIF('เวลา 6'!C5:AX5, "ล") + COUNTIF('เวลา 5'!C5:AX5, "ล") + COUNTIF('เวลา 4'!C5:AR5, "ล") + COUNTIF(เวลา3!C5:AY5, "ล") + COUNTIF(เวลา2!C5:AZ5, "ล") + COUNTIF(เวลา1!G5:AD5, "ล"), IF(_xlpm.TotalCount=0, "-", _xlpm.TotalCount))} -> - | AL5: {=_xlfn.LET(_xlpm.TotalCount, COUNTIF(D5:AJ5, "ข") + COUNTIF('เวลา 6'!C5:AX5, "ข") + COUNTIF('เวลา 5'!C5:AX5, "ข") + COUNTIF('เวลา 4'!C5:AR5, "ข") + COUNTIF(เวลา3!C5:AY5, "ข") + COUNTIF(เวลา2!C5:AZ5, "ข") + COUNTIF(เวลา1!G5:AD5, "ข"), IF(_xlpm.TotalCount=0, "-", _xlpm.TotalCount))} -> 2 | AM5: {=_xlfn.LET(_xlpm.TotalCount, COUNTIF(D5:AJ5, "/") + COUNTIF('เวลา 6'!C5:AX5, "/") + COUNTIF('เวลา 5'!C5:AX5, "/") + COUNTIF('เวลา 4'!C5:AR5, "/") + COUNTIF(เวลา3!C5:AY5, "/") + COUNTIF(เวลา2!C5:AZ5, "/") + COUNTIF(เวลา1!G5:AD5, "/"), IF(_xlpm.TotalCount=0, "-", _xlpm.TotalCount))} -> 198 | AN5: =(AM5/SUM(AK5:AM5))*100 -> 99
B6: 2 | D6: / | E6: / | F6: / | G6: / | H6: / | K6: / | L6: / | M6: / | N6: / | O6: / | R6: / | S6: / | T6: / | U6: / | V6: / | Y6: / | Z6: / | AA6: / | AB6: / | AC6: / | AF6: / | AG6: / | AH6: / | AI6: / | AJ6: / | AK6: {=_xlfn.LET(_xlpm.TotalCount, COUNTIF(D6:AJ6, "ล") + COUNTIF('เวลา 6'!C6:AX6, "ล") + COUNTIF('เวลา 5'!C6:AX6, "ล") + COUNTIF('เวลา 4'!C6:AR6, "ล") + COUNTIF(เวลา3!C6:AY6, "ล") + COUNTIF(เวลา2!C6:AZ6, "ล") + COUNTIF(เวลา1!G6:AD6, "ล"), IF(_xlpm.TotalCount=0, "-", _xlpm.TotalCount))} -> - | AL6: {=_xlfn.LET(_xlpm.TotalCount, COUNTIF(D6:AJ6, "ข") + COUNTIF('เวลา 6'!C6:AX6, "ข") + COUNTIF('เวลา 5'!C6:AX6, "ข") + COUNTIF('เวลา 4'!C6:AR6, "ข") + COUNTIF(เวลา3!C6:AY6, "ข") + COUNTIF(เวลา2!C6:AZ6, "ข") + COUNTIF(เวลา1!G6:AD6, "ข"), IF(_xlpm.TotalCount=0, "-", _xlpm.TotalCount))} -> 2 | AM6: {=_xlfn.LET(_xlpm.TotalCount, COUNTIF(D6:AJ6, "/") + COUNTIF('เวลา 6'!C6:AX6, "/") + COUNTIF('เวลา 5'!C6:AX6, "/") + COUNTIF('เวลา 4'!C6:AR6, "/") + COUNTIF(เวลา3!C6:AY6, "/") + COUNTIF(เวลา2!C6:AZ6, "/") + COUNTIF(เวลา1!G6:AD6, "/"), IF(_xlpm.TotalCount=0, "-", _xlpm.TotalCount))} -> 198 | AN6: =(AM6/SUM(AK6:AM6))*100 -> 99
B7: 3 | D7: / | E7: / | F7: / | G7: / | H7: / | K7: / | L7: / | M7: / | N7: / | O7: / | R7: / | S7: / | T7: / | U7: / | V7: / | Y7: / | Z7: / | AA7: / | AB7: / | AC7: / | AF7: / | AG7: / | AH7: / | AI7: / | AJ7: / | AK7: {=_xlfn.LET(_xlpm.TotalCount, COUNTIF(D7:AJ7, "ล") + COUNTIF('เวลา 6'!C7:AX7, "ล") + COUNTIF('เวลา 5'!C7:AX7, "ล") + COUNTIF('เวลา 4'!C7:AR7, "ล") + COUNTIF(เวลา3!C7:AY7, "ล") + COUNTIF(เวลา2!C7:AZ7, "ล") + COUNTIF(เวลา1!G7:AD7, "ล"), IF(_xlpm.TotalCount=0, "-", _xlpm.TotalCount))} -> 1 | AL7: {=_xlfn.LET(_xlpm.TotalCount, COUNTIF(D7:AJ7, "ข") + COUNTIF('เวลา 6'!C7:AX7, "ข") + COUNTIF('เวลา 5'!C7:AX7, "ข") + COUNTIF('เวลา 4'!C7:AR7, "ข") + COUNTIF(เวลา3!C7:AY7, "ข") + COUNTIF(เวลา2!C7:AZ7, "ข") + COUNTIF(เวลา1!G7:AD7, "ข"), IF(_xlpm.TotalCount=0, "-", _xlpm.TotalCount))} -> 3 | AM7: {=_xlfn.LET(_xlpm.TotalCount, COUNTIF(D7:AJ7, "/") + COUNTIF('เวลา 6'!C7:AX7, "/") + COUNTIF('เวลา 5'!C7:AX7, "/") + COUNTIF('เวลา 4'!C7:AR7, "/") + COUNTIF(เวลา3!C7:AY7, "/") + COUNTIF(เวลา2!C7:AZ7, "/") + COUNTIF(เวลา1!G7:AD7, "/"), IF(_xlpm.TotalCount=0, "-", _xlpm.TotalCount))} -> 196 | AN7: =(AM7/SUM(AK7:AM7))*100 -> 98
B8: 4 | D8: / | E8: / | F8: / | G8: / | H8: / | K8: / | L8: / | M8: / | N8: / | O8: / | R8: / | S8: / | T8: / | U8: / | V8: / | Y8: / | Z8: / | AA8: / | AB8: / | AC8: / | AF8: / | AG8: / | AH8: / | AI8: / | AJ8: / | AK8: {=_xlfn.LET(_xlpm.TotalCount, COUNTIF(D8:AJ8, "ล") + COUNTIF('เวลา 6'!C8:AX8, "ล") + COUNTIF('เวลา 5'!C8:AX8, "ล") + COUNTIF('เวลา 4'!C8:AR8, "ล") + COUNTIF(เวลา3!C8:AY8, "ล") + COUNTIF(เวลา2!C8:AZ8, "ล") + COUNTIF(เวลา1!G8:AD8, "ล"), IF(_xlpm.TotalCount=0, "-", _xlpm.TotalCount))} -> - | AL8: {=_xlfn.LET(_xlpm.TotalCount, COUNTIF(D8:AJ8, "ข") + COUNTIF('เวลา 6'!C8:AX8, "ข") + COUNTIF('เวลา 5'!C8:AX8, "ข") + COUNTIF('เวลา 4'!C8:AR8, "ข") + COUNTIF(เวลา3!C8:AY8, "ข") + COUNTIF(เวลา2!C8:AZ8, "ข") + COUNTIF(เวลา1!G8:AD8, "ข"), IF(_xlpm.TotalCount=0, "-", _xlpm.TotalCount))} -> 3 | AM8: {=_xlfn.LET(_xlpm.TotalCount, COUNTIF(D8:AJ8, "/") + COUNTIF('เวลา 6'!C8:AX8, "/") + COUNTIF('เวลา 5'!C8:AX8, "/") + COUNTIF('เวลา 4'!C8:AR8, "/") + COUNTIF(เวลา3!C8:AY8, "/") + COUNTIF(เวลา2!C8:AZ8, "/") + COUNTIF(เวลา1!G8:AD8, "/"), IF(_xlpm.TotalCount=0, "-", _xlpm.TotalCount))} -> 197 | AN8: =(AM8/SUM(AK8:AM8))*100 -> 98.5
B9: 5 | D9: / | E9: / | F9: / | G9: / | H9: / | K9: / | L9: / | M9: / | N9: / | O9: / | R9: / | S9: / | T9: / | U9: / | V9: / | Y9: / | Z9: / | AA9: / | AB9: / | AC9: / | AF9: / | AG9: / | AH9: / | AI9: / | AJ9: / | AK9: {=_xlfn.LET(_xlpm.TotalCount, COUNTIF(D9:AJ9, "ล") + COUNTIF('เวลา 6'!C9:AX9, "ล") + COUNTIF('เวลา 5'!C9:AX9, "ล") + COUNTIF('เวลา 4'!C9:AR9, "ล") + COUNTIF(เวลา3!C9:AY9, "ล") + COUNTIF(เวลา2!C9:AZ9, "ล") + COUNTIF(เวลา1!G9:AD9, "ล"), IF(_xlpm.TotalCount=0, "-", _xlpm.TotalCount))} -> 3 | AL9: {=_xlfn.LET(_xlpm.TotalCount, COUNTIF(D9:AJ9, "ข") + COUNTIF('เวลา 6'!C9:AX9, "ข") + COUNTIF('เวลา 5'!C9:AX9, "ข") + COUNTIF('เวลา 4'!C9:AR9, "ข") + COUNTIF(เวลา3!C9:AY9, "ข") + COUNTIF(เวลา2!C9:AZ9, "ข") + COUNTIF(เวลา1!G9:AD9, "ข"), IF(_xlpm.TotalCount=0, "-", _xlpm.TotalCount))} -> 2 | AM9: {=_xlfn.LET(_xlpm.TotalCount, COUNTIF(D9:AJ9, "/") + COUNTIF('เวลา 6'!C9:AX9, "/") + COUNTIF('เวลา 5'!C9:AX9, "/") + COUNTIF('เวลา 4'!C9:AR9, "/") + COUNTIF(เวลา3!C9:AY9, "/") + COUNTIF(เวลา2!C9:AZ9, "/") + COUNTIF(เวลา1!G9:AD9, "/"), IF(_xlpm.TotalCount=0, "-", _xlpm.TotalCount))} -> 195 | AN9: =(AM9/SUM(AK9:AM9))*100 -> 97.5
B10: 6 | D10: / | E10: / | F10: / | G10: / | H10: / | K10: / | L10: / | M10: / | N10: / | O10: / | R10: / | S10: / | T10: / | U10: / | V10: / | Y10: / | Z10: / | AA10: / | AB10: / | AC10: / | AF10: / | AG10: / | AH10: / | AI10: / | AJ10: / | AK10: {=_xlfn.LET(_xlpm.TotalCount, COUNTIF(D10:AJ10, "ล") + COUNTIF('เวลา 6'!C10:AX10, "ล") + COUNTIF('เวลา 5'!C10:AX10, "ล") + COUNTIF('เวลา 4'!C10:AR10, "ล") + COUNTIF(เวลา3!C10:AY10, "ล") + COUNTIF(เวลา2!C10:AZ10, "ล") + COUNTIF(เวลา1!G10:AD10, "ล"), IF(_xlpm.TotalCount=0, "-", _xlpm.TotalCount))} -> 2 | AL10: {=_xlfn.LET(_xlpm.TotalCount, COUNTIF(D10:AJ10, "ข") + COUNTIF('เวลา 6'!C10:AX10, "ข") + COUNTIF('เวลา 5'!C10:AX10, "ข") + COUNTIF('เวลา 4'!C10:AR10, "ข") + COUNTIF(เวลา3!C10:AY10, "ข") + COUNTIF(เวลา2!C10:AZ10, "ข") + COUNTIF(เวลา1!G10:AD10, "ข"), IF(_xlpm.TotalCount=0, "-", _xlpm.TotalCount))} -> 1 | AM10: {=_xlfn.LET(_xlpm.TotalCount, COUNTIF(D10:AJ10, "/") + COUNTIF('เวลา 6'!C10:AX10, "/") + COUNTIF('เวลา 5'!C10:AX10, "/") + COUNTIF('เวลา 4'!C10:AR10, "/") + COUNTIF(เวลา3!C10:AY10, "/") + COUNTIF(เวลา2!C10:AZ10, "/") + COUNTIF(เวลา1!G10:AD10, "/"), IF(_xlpm.TotalCount=0, "-", _xlpm.TotalCount))} -> 197 | AN10: =(AM10/SUM(AK10:AM10))*100 -> 98.5
B11: 7 | D11: / | E11: / | F11: / | G11: / | H11: / | K11: / | L11: / | M11: / | N11: / | O11: / | R11: / | S11: / | T11: / | U11: / | V11: / | Y11: / | Z11: / | AA11: / | AB11: / | AC11: / | AF11: / | AG11: / | AH11: / | AI11: / | AJ11: / | AK11: {=_xlfn.LET(_xlpm.TotalCount, COUNTIF(D11:AJ11, "ล") + COUNTIF('เวลา 6'!C11:AX11, "ล") + COUNTIF('เวลา 5'!C11:AX11, "ล") + COUNTIF('เวลา 4'!C11:AR11, "ล") + COUNTIF(เวลา3!C11:AY11, "ล") + COUNTIF(เวลา2!C11:AZ11, "ล") + COUNTIF(เวลา1!G11:AD11, "ล"), IF(_xlpm.TotalCount=0, "-", _xlpm.TotalCount))} -> 3 | AL11: {=_xlfn.LET(_xlpm.TotalCount, COUNTIF(D11:AJ11, "ข") + COUNTIF('เวลา 6'!C11:AX11, "ข") + COUNTIF('เวลา 5'!C11:AX11, "ข") + COUNTIF('เวลา 4'!C11:AR11, "ข") + COUNTIF(เวลา3!C11:AY11, "ข") + COUNTIF(เวลา2!C11:AZ11, "ข") + COUNTIF(เวลา1!G11:AD11, "ข"), IF(_xlpm.TotalCount=0, "-", _xlpm.TotalCount))} -> 1 | AM11: {=_xlfn.LET(_xlpm.TotalCount, COUNTIF(D11:AJ11, "/") + COUNTIF('เวลา 6'!C11:AX11, "/") + COUNTIF('เวลา 5'!C11:AX11, "/") + COUNTIF('เวลา 4'!C11:AR11, "/") + COUNTIF(เวลา3!C11:AY11, "/") + COUNTIF(เวลา2!C11:AZ11, "/") + COUNTIF(เวลา1!G11:AD11, "/"), IF(_xlpm.TotalCount=0, "-", _xlpm.TotalCount))} -> 196 | AN11: =(AM11/SUM(AK11:AM11))*100 -> 98
B12: 8 | D12: / | E12: / | F12: / | G12: / | H12: / | K12: / | L12: / | M12: / | N12: ล | O12: / | R12: / | S12: / | T12: / | U12: / | V12: / | Y12: / | Z12: / | AA12: / | AB12: / | AC12: / | AF12: / | AG12: / | AH12: / | AI12: / | AJ12: / | AK12: {=_xlfn.LET(_xlpm.TotalCount, COUNTIF(D12:AJ12, "ล") + COUNTIF('เวลา 6'!C12:AX12, "ล") + COUNTIF('เวลา 5'!C12:AX12, "ล") + COUNTIF('เวลา 4'!C12:AR12, "ล") + COUNTIF(เวลา3!C12:AY12, "ล") + COUNTIF(เวลา2!C12:AZ12, "ล") + COUNTIF(เวลา1!G12:AD12, "ล"), IF(_xlpm.TotalCount=0, "-", _xlpm.TotalCount))} -> 1 | AL12: {=_xlfn.LET(_xlpm.TotalCount, COUNTIF(D12:AJ12, "ข") + COUNTIF('เวลา 6'!C12:AX12, "ข") + COUNTIF('เวลา 5'!C12:AX12, "ข") + COUNTIF('เวลา 4'!C12:AR12, "ข") + COUNTIF(เวลา3!C12:AY12, "ข") + COUNTIF(เวลา2!C12:AZ12, "ข") + COUNTIF(เวลา1!G12:AD12, "ข"), IF(_xlpm.TotalCount=0, "-", _xlpm.TotalCount))} -> - | AM12: {=_xlfn.LET(_xlpm.TotalCount, COUNTIF(D12:AJ12, "/") + COUNTIF('เวลา 6'!C12:AX12, "/") + COUNTIF('เวลา 5'!C12:AX12, "/") + COUNTIF('เวลา 4'!C12:AR12, "/") + COUNTIF(เวลา3!C12:AY12, "/") + COUNTIF(เวลา2!C12:AZ12, "/") + COUNTIF(เวลา1!G12:AD12, "/"), IF(_xlpm.TotalCount=0, "-", _xlpm.TotalCount))} -> 199 | AN12: =(AM12/SUM(AK12:AM12))*100 -> 99.5
B13: 9 | D13: / | E13: / | F13: / | G13: / | H13: / | K13: / | L13: / | M13: / | N13: / | O13: / | R13: / | S13: / | T13: / | U13: / | V13: / | Y13: / | Z13: / | AA13: / | AB13: / | AC13: / | AF13: / | AG13: / | AH13: / | AI13: / | AJ13: / | AK13: {=_xlfn.LET(_xlpm.TotalCount, COUNTIF(D13:AJ13, "ล") + COUNTIF('เวลา 6'!C13:AX13, "ล") + COUNTIF('เวลา 5'!C13:AX13, "ล") + COUNTIF('เวลา 4'!C13:AR13, "ล") + COUNTIF(เวลา3!C13:AY13, "ล") + COUNTIF(เวลา2!C13:AZ13, "ล") + COUNTIF(เวลา1!G13:AD13, "ล"), IF(_xlpm.TotalCount=0, "-", _xlpm.TotalCount))} -> 2 | AL13: {=_xlfn.LET(_xlpm.TotalCount, COUNTIF(D13:AJ13, "ข") + COUNTIF('เวลา 6'!C13:AX13, "ข") + COUNTIF('เวลา 5'!C13:AX13, "ข") + COUNTIF('เวลา 4'!C13:AR13, "ข") + COUNTIF(เวลา3!C13:AY13, "ข") + COUNTIF(เวลา2!C13:AZ13, "ข") + COUNTIF(เวลา1!G13:AD13, "ข"), IF(_xlpm.TotalCount=0, "-", _xlpm.TotalCount))} -> 1 | AM13: {=_xlfn.LET(_xlpm.TotalCount, COUNTIF(D13:AJ13, "/") + COUNTIF('เวลา 6'!C13:AX13, "/") + COUNTIF('เวลา 5'!C13:AX13, "/") + COUNTIF('เวลา 4'!C13:AR13, "/") + COUNTIF(เวลา3!C13:AY13, "/") + COUNTIF(เวลา2!C13:AZ13, "/") + COUNTIF(เวลา1!G13:AD13, "/"), IF(_xlpm.TotalCount=0, "-", _xlpm.TotalCount))} -> 197 | AN13: =(AM13/SUM(AK13:AM13))*100 -> 98.5
B14: 10 | D14: / | E14: / | F14: ล | G14: / | H14: / | K14: / | L14: / | M14: / | N14: / | O14: / | R14: / | S14: / | T14: / | U14: / | V14: / | Y14: / | Z14: / | AA14: / | AB14: / | AC14: / | AF14: / | AG14: / | AH14: / | AI14: / | AJ14: / | AK14: {=_xlfn.LET(_xlpm.TotalCount, COUNTIF(D14:AJ14, "ล") + COUNTIF('เวลา 6'!C14:AX14, "ล") + COUNTIF('เวลา 5'!C14:AX14, "ล") + COUNTIF('เวลา 4'!C14:AR14, "ล") + COUNTIF(เวลา3!C14:AY14, "ล") + COUNTIF(เวลา2!C14:AZ14, "ล") + COUNTIF(เวลา1!G14:AD14, "ล"), IF(_xlpm.TotalCount=0, "-", _xlpm.TotalCount))} -> 2 | AL14: {=_xlfn.LET(_xlpm.TotalCount, COUNTIF(D14:AJ14, "ข") + COUNTIF('เวลา 6'!C14:AX14, "ข") + COUNTIF('เวลา 5'!C14:AX14, "ข") + COUNTIF('เวลา 4'!C14:AR14, "ข") + COUNTIF(เวลา3!C14:AY14, "ข") + COUNTIF(เวลา2!C14:AZ14, "ข") + COUNTIF(เวลา1!G14:AD14, "ข"), IF(_xlpm.TotalCount=0, "-", _xlpm.TotalCount))} -> 1 | AM14: {=_xlfn.LET(_xlpm.TotalCount, COUNTIF(D14:AJ14, "/") + COUNTIF('เวลา 6'!C14:AX14, "/") + COUNTIF('เวลา 5'!C14:AX14, "/") + COUNTIF('เวลา 4'!C14:AR14, "/") + COUNTIF(เวลา3!C14:AY14, "/") + COUNTIF(เวลา2!C14:AZ14, "/") + COUNTIF(เวลา1!G14:AD14, "/"), IF(_xlpm.TotalCount=0, "-", _xlpm.TotalCount))} -> 197 | AN14: =(AM14/SUM(AK14:AM14))*100 -> 98.5
B15: 11 | D15: / | E15: / | F15: / | G15: / | H15: / | K15: / | L15: / | M15: / | N15: / | O15: / | R15: / | S15: / | T15: / | U15: / | V15: / | Y15: / | Z15: / | AA15: / | AB15: / | AC15: / | AF15: / | AG15: / | AH15: / | AI15: / | AJ15: / | AK15: {=_xlfn.LET(_xlpm.TotalCount, COUNTIF(D15:AJ15, "ล") + COUNTIF('เวลา 6'!C15:AX15, "ล") + COUNTIF('เวลา 5'!C15:AX15, "ล") + COUNTIF('เวลา 4'!C15:AR15, "ล") + COUNTIF(เวลา3!C15:AY15, "ล") + COUNTIF(เวลา2!C15:AZ15, "ล") + COUNTIF(เวลา1!G15:AD15, "ล"), IF(_xlpm.TotalCount=0, "-", _xlpm.TotalCount))} -> 1 | AL15: {=_xlfn.LET(_xlpm.TotalCount, COUNTIF(D15:AJ15, "ข") + COUNTIF('เวลา 6'!C15:AX15, "ข") + COUNTIF('เวลา 5'!C15:AX15, "ข") + COUNTIF('เวลา 4'!C15:AR15, "ข") + COUNTIF(เวลา3!C15:AY15, "ข") + COUNTIF(เวลา2!C15:AZ15, "ข") + COUNTIF(เวลา1!G15:AD15, "ข"), IF(_xlpm.TotalCount=0, "-", _xlpm.TotalCount))} -> 3 | AM15: {=_xlfn.LET(_xlpm.TotalCount, COUNTIF(D15:AJ15, "/") + COUNTIF('เวลา 6'!C15:AX15, "/") + COUNTIF('เวลา 5'!C15:AX15, "/") + COUNTIF('เวลา 4'!C15:AR15, "/") + COUNTIF(เวลา3!C15:AY15, "/") + COUNTIF(เวลา2!C15:AZ15, "/") + COUNTIF(เวลา1!G15:AD15, "/"), IF(_xlpm.TotalCount=0, "-", _xlpm.TotalCount))} -> 196 | AN15: =(AM15/SUM(AK15:AM15))*100 -> 98
B16: 12 | D16: / | E16: / | F16: / | G16: / | H16: / | K16: / | L16: / | M16: / | N16: / | O16: / | R16: / | S16: / | T16: ข | U16: / | V16: / | Y16: / | Z16: / | AA16: / | AB16: / | AC16: / | AF16: / | AG16: / | AH16: / | AI16: / | AJ16: / | AK16: {=_xlfn.LET(_xlpm.TotalCount, COUNTIF(D16:AJ16, "ล") + COUNTIF('เวลา 6'!C16:AX16, "ล") + COUNTIF('เวลา 5'!C16:AX16, "ล") + COUNTIF('เวลา 4'!C16:AR16, "ล") + COUNTIF(เวลา3!C16:AY16, "ล") + COUNTIF(เวลา2!C16:AZ16, "ล") + COUNTIF(เวลา1!G16:AD16, "ล"), IF(_xlpm.TotalCount=0, "-", _xlpm.TotalCount))} -> 1 | AL16: {=_xlfn.LET(_xlpm.TotalCount, COUNTIF(D16:AJ16, "ข") + COUNTIF('เวลา 6'!C16:AX16, "ข") + COUNTIF('เวลา 5'!C16:AX16, "ข") + COUNTIF('เวลา 4'!C16:AR16, "ข") + COUNTIF(เวลา3!C16:AY16, "ข") + COUNTIF(เวลา2!C16:AZ16, "ข") + COUNTIF(เวลา1!G16:AD16, "ข"), IF(_xlpm.TotalCount=0, "-", _xlpm.TotalCount))} -> 2 | AM16: {=_xlfn.LET(_xlpm.TotalCount, COUNTIF(D16:AJ16, "/") + COUNTIF('เวลา 6'!C16:AX16, "/") + COUNTIF('เวลา 5'!C16:AX16, "/") + COUNTIF('เวลา 4'!C16:AR16, "/") + COUNTIF(เวลา3!C16:AY16, "/") + COUNTIF(เวลา2!C16:AZ16, "/") + COUNTIF(เวลา1!G16:AD16, "/"), IF(_xlpm.TotalCount=0, "-", _xlpm.TotalCount))} -> 197 | AN16: =(AM16/SUM(AK16:AM16))*100 -> 98.5
B17: 13 | D17: / | E17: / | F17: / | G17: / | H17: / | K17: / | L17: / | M17: / | N17: / | O17: / | R17: / | S17: / | T17: / | U17: / | V17: / | Y17: / | Z17: / | AA17: / | AB17: / | AC17: / | AF17: / | AG17: / | AH17: / | AI17: / | AJ17: / | AK17: {=_xlfn.LET(_xlpm.TotalCount, COUNTIF(D17:AJ17, "ล") + COUNTIF('เวลา 6'!C17:AX17, "ล") + COUNTIF('เวลา 5'!C17:AX17, "ล") + COUNTIF('เวลา 4'!C17:AR17, "ล") + COUNTIF(เวลา3!C17:AY17, "ล") + COUNTIF(เวลา2!C17:AZ17, "ล") + COUNTIF(เวลา1!G17:AD17, "ล"), IF(_xlpm.TotalCount=0, "-", _xlpm.TotalCount))} -> - | AL17: {=_xlfn.LET(_xlpm.TotalCount, COUNTIF(D17:AJ17, "ข") + COUNTIF('เวลา 6'!C17:AX17, "ข") + COUNTIF('เวลา 5'!C17:AX17, "ข") + COUNTIF('เวลา 4'!C17:AR17, "ข") + COUNTIF(เวลา3!C17:AY17, "ข") + COUNTIF(เวลา2!C17:AZ17, "ข") + COUNTIF(เวลา1!G17:AD17, "ข"), IF(_xlpm.TotalCount=0, "-", _xlpm.TotalCount))} -> - | AM17: {=_xlfn.LET(_xlpm.TotalCount, COUNTIF(D17:AJ17, "/") + COUNTIF('เวลา 6'!C17:AX17, "/") + COUNTIF('เวลา 5'!C17:AX17, "/") + COUNTIF('เวลา 4'!C17:AR17, "/") + COUNTIF(เวลา3!C17:AY17, "/") + COUNTIF(เวลา2!C17:AZ17, "/") + COUNTIF(เวลา1!G17:AD17, "/"), IF(_xlpm.TotalCount=0, "-", _xlpm.TotalCount))} -> 200 | AN17: =(AM17/SUM(AK17:AM17))*100 -> 100
C18: 13

Sheet คะแนน1
B1: เลขที่ | C1: ชื่อ - สกุล | D1: ตัวชี้วัดการเรียนรู้ | E1: คะแนนระหว่างเรียน
E2: ตัวชี้วัดการเรียนรู้/ผลการเรียนรู้ที่คาดหวัง
E3: ต 1.1 ป.1/1 | F3: ต 1.1 ป.1/3 | G3: ต 1.2 ป.1/1 | H3: ต 1.2 ป.1/2 | I3: ต 1.2 ป.1/3 | J3: ต 1.2 ป.1/4 | K3: ต 2.1 ป.1/1 | L3: ต 2.1 ป.1/2 | M3: ต 2.2 ป.1/1 | N3: ต 3.1 ป.1/1 | O3: ต 1.1 ป.1/2 | P3: ต 1.1 ป.1/4 | Q3: ต 1.3 ป.1/1 | R3: ต 2.1 ป.1/3 | S3: ต 4.1 ป.1/1 | T3: ต 4.2 ป.1/1
D4: คะแนน | E4: 3 | F4: 3 | G4: 3 | H4: 3 | I4: 3 | J4: 3 | K4: 3 | L4: 3 | M4: 3 | N4: 3 | O4: 3 | P4: 3 | Q4: 3 | R4: 3 | S4: 3 | T4: 3
B5: 1 | C5: =ข้อมูลเด็ก!F6 -> เด็กชายปัณณวิชญ์ เปรียงพรม | E5: 3 | F5: 2 | G5: 3 | H5: 2 | I5: 3 | J5: 3 | K5: 3 | L5: 3 | M5: 2 | N5: 3 | O5: 3 | P5: 3 | Q5: 3 | R5: 2 | S5: 3 | T5: 2
B6: 2 | C6: =ข้อมูลเด็ก!F7 -> เด็กชายรัชชานนท์ เทียมกลาง | E6: 3 | F6: 3 | G6: 3 | H6: 3 | I6: 3 | J6: 3 | K6: 3 | L6: 3 | M6: 3 | N6: 2 | O6: 3 | P6: 3 | Q6: 3 | R6: 3 | S6: 2 | T6: 2
B7: 3 | C7: =ข้อมูลเด็ก!F8 -> เด็กชายรณกฤต สองเมือง | E7: 3 | F7: 3 | G7: 3 | H7: 3 | I7: 2 | J7: 2 | K7: 2 | L7: 3 | M7: 3 | N7: 2 | O7: 2 | P7: 3 | Q7: 2 | R7: 3 | S7: 2 | T7: 3
B8: 4 | C8: =ข้อมูลเด็ก!F9 -> เด็กหญิงกรรณิการ์ คงสุดี | E8: 3 | F8: 3 | G8: 2 | H8: 2 | I8: 3 | J8: 3 | K8: 2 | L8: 3 | M8: 3 | N8: 3 | O8: 2 | P8: 2 | Q8: 3 | R8: 2 | S8: 3 | T8: 2
B9: 5 | C9: =ข้อมูลเด็ก!F10 -> เด็กหญิงชญานิศ พันธุเมฆ | E9: 3 | F9: 3 | G9: 2 | H9: 3 | I9: 2 | J9: 3 | K9: 2 | L9: 2 | M9: 3 | N9: 3 | O9: 3 | P9: 3 | Q9: 3 | R9: 3 | S9: 3 | T9: 2
B10: 6 | C10: =ข้อมูลเด็ก!F11 -> เด็กหญิงปนัดดา โพธิสุวรรณ | E10: 3 | F10: 3 | G10: 3 | H10: 2 | I10: 2 | J10: 3 | K10: 3 | L10: 3 | M10: 3 | N10: 3 | O10: 2 | P10: 2 | Q10: 3 | R10: 3 | S10: 3 | T10: 2
B11: 7 | C11: =ข้อมูลเด็ก!F12 -> เด็กหญิงรุ่งนภา ผดุงภักดี | E11: 3 | F11: 3 | G11: 2 | H11: 3 | I11: 2 | J11: 2 | K11: 3 | L11: 2 | M11: 2 | N11: 2 | O11: 3 | P11: 2 | Q11: 2 | R11: 3 | S11: 3 | T11: 3
B12: 8 | C12: =ข้อมูลเด็ก!F13 -> เด็กหญิงพิมพิ์พิชชา มะลิมาตย์ | E12: 3 | F12: 2 | G12: 2 | H12: 3 | I12: 2 | J12: 3 | K12: 3 | L12: 3 | M12: 3 | N12: 2 | O12: 3 | P12: 3 | Q12: 2 | R12: 3 | S12: 3 | T12: 3
B13: 9 | C13: =ข้อมูลเด็ก!F14 -> เด็กหญิงพิมพ์รดา เม้าราษี | E13: 3 | F13: 3 | G13: 3 | H13: 2 | I13: 3 | J13: 3 | K13: 2 | L13: 3 | M13: 3 | N13: 3 | O13: 2 | P13: 3 | Q13: 2 | R13: 3 | S13: 3 | T13: 3
B14: 10 | C14: =ข้อมูลเด็ก!F15 -> เด็กหญิงศศิวิมล ธนูทอง | E14: 3 | F14: 3 | G14: 3 | H14: 3 | I14: 2 | J14: 3 | K14: 2 | L14: 2 | M14: 3 | N14: 3 | O14: 3 | P14: 3 | Q14: 3 | R14: 3 | S14: 3 | T14: 2
B15: 11 | C15: =ข้อมูลเด็ก!F16 -> เด็กชายปัณณวิชญ์ พันธ์เดช | E15: 3 | F15: 3 | G15: 2 | H15: 3 | I15: 3 | J15: 3 | K15: 3 | L15: 3 | M15: 3 | N15: 3 | O15: 2 | P15: 2 | Q15: 3 | R15: 2 | S15: 3 | T15: 2
B16: 12 | C16: =ข้อมูลเด็ก!F17 -> เด็กหญิงสุชาดา ชมภูนาค | E16: 3 | F16: 2 | G16: 3 | H16: 3 | I16: 3 | J16: 3 | K16: 3 | L16: 2 | M16: 2 | N16: 2 | O16: 3 | P16: 3 | Q16: 2 | R16: 2 | S16: 3 | T16: 3
B17: 13 | C17: =ข้อมูลเด็ก!F18 -> เด็กหญิงอริสา วรเลิศ | E17: 3 | F17: 2 | G17: 3 | H17: 3 | I17: 3 | J17: 3 | K17: 3 | L17: 2 | M17: 2 | N17: 2 | O17: 3 | P17: 3 | Q17: 2 | R17: 2 | S17: 3 | T17: 3

Sheet คะแนน2
B1: เลขที่ | C1: ชื่อ - สกุล | D1: ตัวชี้วัดการเรียนรู้ | E1: คะแนนระหว่างเรียน | Q1: รวมคะแนน | U1: ผลการประเมิน | V1: สอบแก้ตัว
E2: ตัวชี้วัดการเรียนรู้/ผลการเรียนรู้ที่คาดหวัง | Q2: ระหว่างเรียน | R2: สอบกลางภาค | S2: สอบปลาภาค | T2: ทั้งหมด
D4: คะแนน | Q4: 50 | R4: 20 | S4: 30 | T4: 100
B5: 1 | C5: =ข้อมูลเด็ก!F6 -> เด็กชายปัณณวิชญ์ เปรียงพรม | Q5: 42 | R5: 18 | S5: 22 | T5: =SUM(Q5:S5) -> 82 | U5: =IF(T5="","",IF(T5>=80,4,IF(T5>=75,3.5,IF(T5>=70,3,IF(T5>=65,2.5,IF(T5>=60,2,IF(T5>=55,1.5,IF(T5>=50,1,0)))))))) -> 4
B6: 2 | C6: =ข้อมูลเด็ก!F7 -> เด็กชายรัชชานนท์ เทียมกลาง | Q6: 40 | R6: 12 | S6: 20 | T6: =SUM(Q6:S6) -> 72 | U6: =IF(T6="","",IF(T6>=80,4,IF(T6>=75,3.5,IF(T6>=70,3,IF(T6>=65,2.5,IF(T6>=60,2,IF(T6>=55,1.5,IF(T6>=50,1,0)))))))) -> 3
B7: 3 | C7: =ข้อมูลเด็ก!F8 -> เด็กชายรณกฤต สองเมือง | Q7: 35 | R7: 15 | S7: 20 | T7: =SUM(Q7:S7) -> 70 | U7: =IF(T7="","",IF(T7>=80,4,IF(T7>=75,3.5,IF(T7>=70,3,IF(T7>=65,2.5,IF(T7>=60,2,IF(T7>=55,1.5,IF(T7>=50,1,0)))))))) -> 3
B8: 4 | C8: =ข้อมูลเด็ก!F9 -> เด็กหญิงกรรณิการ์ คงสุดี | Q8: 40 | R8: 19 | S8: 23 | T8: =SUM(Q8:S8) -> 82 | U8: =IF(T8="","",IF(T8>=80,4,IF(T8>=75,3.5,IF(T8>=70,3,IF(T8>=65,2.5,IF(T8>=60,2,IF(T8>=55,1.5,IF(T8>=50,1,0)))))))) -> 4
B9: 5 | C9: =ข้อมูลเด็ก!F10 -> เด็กหญิงชญานิศ พันธุเมฆ | Q9: 35 | R9: 15 | S9: 20 | T9: =SUM(Q9:S9) -> 70 | U9: =IF(T9="","",IF(T9>=80,4,IF(T9>=75,3.5,IF(T9>=70,3,IF(T9>=65,2.5,IF(T9>=60,2,IF(T9>=55,1.5,IF(T9>=50,1,0)))))))) -> 3
B10: 6 | C10: =ข้อมูลเด็ก!F11 -> เด็กหญิงปนัดดา โพธิสุวรรณ | Q10: 47 | R10: 17 | S10: 18 | T10: =SUM(Q10:S10) -> 82 | U10: =IF(T10="","",IF(T10>=80,4,IF(T10>=75,3.5,IF(T10>=70,3,IF(T10>=65,2.5,IF(T10>=60,2,IF(T10>=55,1.5,IF(T10>=50,1,0)))))))) -> 4
B11: 7 | C11: =ข้อมูลเด็ก!F12 -> เด็กหญิงรุ่งนภา ผดุงภักดี | Q11: 43 | R11: 18 | S11: 22 | T11: =SUM(Q11:S11) -> 83 | U11: =IF(T11="","",IF(T11>=80,4,IF(T11>=75,3.5,IF(T11>=70,3,IF(T11>=65,2.5,IF(T11>=60,2,IF(T11>=55,1.5,IF(T11>=50,1,0)))))))) -> 4
